Workbook

Sheet data
A1: 序号 | B1: 关单号/提单号 | C1: 发货人 名称 | D1: 发货人 地址 | E1: 发货人 城市 | F1: 发货人 地区编码 | G1: 发货人 联系电话 | H1: 发货人 企业编码 | I1: 收货人 名称 | J1: 收货人 地址 | K1: 收货人 城市 | L1: 收货人 地区编码 | M1: 收货人 联系电话 | N1: 收货人 企业编码 | O1: 通知人 名称 | P1: 通知人 地址 | Q1: 通知人 城市 | R1: 通知人 地区编码 | S1: 通知人 联系电话 | T1: 通知人 企业编码 | U1: 箱号 | V1: 尺寸箱型 | W1: 铅封号 | X1: 件数 | Y1: 包装 | Z1: 货物毛重 (kg) | AA1: 体积 (m3) | AB1: 唛头 | AC1: 品名 | AD1: 中转港 | AE1: 目的港 | AF1: 付费方式 | AG1: 运输条款代码 | AH1: 危险品 级别 (Class) | AI1: 危险品 编码 (UN No.) | AJ1: 危险品 联系人姓名 | AK1: 危险品 联系人通讯号码 | AM1: Valid | AN1: 校验信息
A2: 1 | B2: OOLU2162875160 | C2: Suzhou Sudelan Railway Parts Co., Ltd. | D2: No.112 Xinjiang Road,Fuqiao town,Taicang City | F2: CN | G2: 18012719858 | I2: Rodolphe Gruchy of PANDROL SAS-Usine de DOUAI | J2: SDM Expédition N°105 Rue Paul Foucaut 59450 SIN-LE-NOBLE France | L2: FR | M2: 33 647568635 | O2: Rodolphe Gruchy of PANDROL SAS-Usine de DOUAI | P2: SDM Expédition N°105 Rue Paul Foucaut 59450 SIN-LE-NOBLE France | R2: FR | S2: 33 647568635 | U2: BSIU2683177 | V2: 20GP | W2: OOLKFB8313 | X2: 36 | Y2: CS | Z2: 24624 | AA2: 19.08 | AB2: COMMANDE CA2504338 SUDELAN SO2502312 – COTE D' IVOIRE Quantity: Description: Case No: Batch No: | AC2: Coach screw | AE2: BEANR | AF2: CC | AG2: PP | AM2: =checking!A2 -> FALSE | AN2: =IF(NOT(AM2), checking!AX2,"") -> 缺少 发货人城市 缺少 收货人城市 缺少 通知人城市 唛头 不应多于90个字符
A3: =IF(ISBLANK(B3), "", A2+1) -> 2 | B3: OOLU2162875160 | C3: Suzhou Sudelan Railway Parts Co., Ltd. | D3: No.112 Xinjiang Road,Fuqiao town,Taicang City | F3: CN | G3: 18012719858 | I3: Rodolphe Gruchy of PANDROL SAS-Usine de DOUAI | J3: SDM Expédition N°105 Rue Paul Foucaut 59450 SIN-LE-NOBLE France | L3: FR | M3: 33 647568635 | O3: Rodolphe Gruchy of PANDROL SAS-Usine de DOUAI | P3: SDM Expédition N°105 Rue Paul Foucaut 59450 SIN-LE-NOBLE France | R3: FR | S3: 33 647568635 | U3: FCIU5241382 | V3: 20GP | W3: OOLKFB8312 | X3: 36 | Y3: CS | Z3: 24624 | AA3: 19.08 | AB3: COMMANDE CA2504338 SUDELAN SO2502312 – COTE D' IVOIRE Quantity: Description: Case No: Batch No: | AC3: Coach screw | AE3: BEANR | AF3: CC | AG3: PP | AM3: =checking!A3 -> FALSE | AN3: =IF(NOT(AM3), checking!AX3,"") -> 缺少 发货人城市 缺少 收货人城市 缺少 通知人城市 唛头 不应多于90个字符
A4: =IF(ISBLANK(B4), "", A3+1) -> 3 | B4: OOLU2162875160 | C4: Suzhou Sudelan Railway Parts Co., Ltd. | D4: No.112 Xinjiang Road,Fuqiao town,Taicang City | F4: CN | G4: 18012719858 | I4: Rodolphe Gruchy of PANDROL SAS-Usine de DOUAI | J4: SDM Expédition N°105 Rue Paul Foucaut 59450 SIN-LE-NOBLE France | L4: FR | M4: 33 647568635 | O4: Rodolphe Gruchy of PANDROL SAS-Usine de DOUAI | P4: SDM Expédition N°105 Rue Paul Foucaut 59450 SIN-LE-NOBLE France | R4: FR | S4: 33 647568635 | U4: OOLU0374646 | V4: 20GP | W4: OOLKEU7154 | X4: 36 | Y4: CS | Z4: 24624 | AA4: 19.08 | AB4: COMMANDE CA2504338 SUDELAN SO2502312 – COTE D' IVOIRE Quantity: Description: Case No: Batch No: | AC4: Coach screw | AE4: BEANR | AF4: CC | AG4: PP | AM4: =checking!A4 -> FALSE | AN4: =IF(NOT(AM4), checking!AX4,"") -> 缺少 发货人城市 缺少 收货人城市 缺少 通知人城市 唛头 不应多于90个字符
A5: =IF(ISBLANK(B5), "", A4+1) | AM5: =checking!A5 -> TRUE | AN5: =IF(NOT(AM5), checking!AX5,"")
A6: =IF(ISBLANK(B6), "", A5+1) | AM6: =checking!A6 -> TRUE | AN6: =IF(NOT(AM6), checking!AX6,"")
A7: =IF(ISBLANK(B7), "", A6+1) | AM7: =checking!A7 -> TRUE | AN7: =IF(NOT(AM7), checking!AX7,"")
A8: =IF(ISBLANK(B8), "", A7+1) | AM8: =checking!A8 -> TRUE | AN8: =IF(NOT(AM8), checking!AX8,"")
A9: =IF(ISBLANK(B9), "", A8+1) | AM9: =checking!A9 -> TRUE | AN9: =IF(NOT(AM9), checking!AX9,"")
A10: =IF(ISBLANK(B10), "", A9+1) | AM10: =checking!A10 -> TRUE | AN10: =IF(NOT(AM10), checking!AX10,"")
A11: =IF(ISBLANK(B11), "", A10+1) | AM11: =checking!A11 -> TRUE | AN11: =IF(NOT(AM11), checking!AX11,"")
A12: =IF(ISBLANK(B12), "", A11+1) | AM12: =checking!A12 -> TRUE | AN12: =IF(NOT(AM12), checking!AX12,"")
A13: =IF(ISBLANK(B13), "", A12+1) | AM13: =checking!A13 -> TRUE | AN13: =IF(NOT(AM13), checking!AX13,"")
A14: =IF(ISBLANK(B14), "", A13+1) | AM14: =checking!A14 -> TRUE | AN14: =IF(NOT(AM14), checking!AX14,"")
A15: =IF(ISBLANK(B15), "", A14+1) | AM15: =checking!A15 -> TRUE | AN15: =IF(NOT(AM15), checking!AX15,"")
A16: =IF(ISBLANK(B16), "", A15+1) | AM16: =checking!A16 -> TRUE | AN16: =IF(NOT(AM16), checking!AX16,"")
... A277: =IF(ISBLANK(B277), "", A276+1) | AM277: =checking!A277 -> TRUE | AN277: =IF(NOT(AM277), checking!AX277,"")

Sheet 箱型尺寸
A1: 箱型尺寸 | B1: ISO 编码 | C1: Description
A2: 20FL | B2: 22P3 | C2: 20' Flatrack
A3: 20GP | B3: 22G0 | C3: 20' General Purpose
A4: 20HG | B4: 22G9 | C4: 20' General Purpose with Hanger
A5: 20HQ | B5: 25G1 | C5: 20' High Cube
A6: 20OT | B6: 22U1 | C6: 20' Open Top
A7: 20RF | B7: 22R1 | C7: 20' Reefer
A8: 20TK | B8: 22T5 | C8: 20' Tank
A9: 40FL | B9: 42P3 | C9: 40' Flatrack
A10: 40FQ | B10: 45P3 | C10: 40' Flatrack High Cube
A11: 40GP | B11: 42G0 | C11: 40' General Purpose
A12: 40HG | B12: 42G9 | C12: 40' General Purpose with Hanger
... A19: 45HQ | B19: L5G1 | C19: 45' High Cube

Sheet 包装代码
A1: 包装代码 | B1: 包装名称
A2: AA | B2: Aluminium Crate
A3: AB | B3: aluminium box w.water resistant coating (4B)
A4: AC | B4: Angle Crate
A5: AD | B5: aluminium drum-removable head (1B2)
A6: AE | B6: Textile Bag
A7: AI | B7: Solid Plastic Box
A8: AJ | B8: aluminium jerrican-removable head (3B2)
A9: AM | B9: Ampoule
A10: AR | B10: Bar
A11: AS | B11: Carcass
A12: AT | B12: Steel Crate
... A252: WZ | B252: wooden box

Sheet 付款方式
A1: 代码 | B1: 付款方式名称
A2: PP | B2: Prepaid 预付
A3: CC | B3: Collect 到付

Sheet 地区编码
A1: 地区编码 | B1: 名称
A2: AD | B2: Andorra | C2: 安道尔
A3: AE | B3: United Arab Emirates | C3: 阿拉伯联合酋长国
A4: AF | B4: Afghanistan | C4: 阿富汗
A5: AG | B5: Antigua and Barbuda | C5: 安提瓜和巴布达
A6: AI | B6: Anguilla | C6: 安圭拉
A7: AL | B7: Albania | C7: 阿尔巴尼亚
A8: AM | B8: Armenia | C8: 亚美尼亚
A9: AO | B9: Angola | C9: 安哥拉
A10: AQ | B10: Antarctica | C10: 南极洲
A11: AR | B11: Argentina | C11: 阿根廷
A12: AS | B12: American Samoa | C12: 美属萨摩亚
A13: AT | B13: Austria | C13: 奥地利
... A250: ZW | B250: Zimbabwe | C250: 津巴布韦

Sheet 运输条款
A1: 代码 | B1: 运输条款
A2: PP | B2: Pier to Pier
A3: HH | B3: House to House
A4: PH | B4: Pier to House
A5: HP | B5: House to Pier

Sheet 港口代码
A1: 港口代码 | B1: 港口名称
A2: DKAAL | B2: Aalborg
A3: DKAAR | B3: Aarhus
A4: GBABD | B4: Aberdeen
A5: CIABJ | B5: Abidjan
A6: AEAUH | B6: Abu Dhabi
A7: JPABU | B7: Aburatsu
A8: SVAQJ | B8: Acajutla
A9: AUADL | B9: Adelaide
A10: AEAUH | B10: Aeruw
A11: MAAGA | B11: Agadir
A12: SEAHU | B12: Ahus
... A685: BEZEE | B685: Zeebrugge

Sheet rule_mapping
A1: TRAFFIC_MDE | B1: PAYMENT_METHOD | C1: INTL_SIZE_TYPE | D1: PACKAGE_CDE
A2: HH | B2: PP | C2: 20LQ | D2: AA
A3: PP | B3: CC | C3: 20LQ | D3: AB
A4: PH | C4: 20IH | D4: AC
A5: HP | C5: 20FL | D5: AD
A6: HD | C6: 20FL | D6: AE
A7: DH | C7: 20FL | D7: AI
A8: DD | C8: 20FL | D8: AJ
C9: 20FL | D9: AM
C10: 20FL | D10: AR
C11: 20TF | D11: AS
C12: 20TK | D12: AT
C13: 20TK | D13: AW
C14: 20TK | D14: BC
C15: 20TK | D15: BD
C16: 20BK | D16: BE
C17: 20AC | D17: BF
C18: 20AC | D18: BG
C19: 20BK | D19: BH
C20: 20LQ | D20: BI
... C252: 40TK | D252: WZ
C253: 40BK
C254: 40AC
C255: 40AC
C256: 40BK
C257: 40HC
C258: 40HH
C259: 40TK
C260: 40HH
C261: 40HH
C262: 40XX
C263: 40XX
C264: 40XX
... C325: 40SR

Sheet checking
A1: All Rule | B1: 关单号 应以OOLU开头 | C1: 缺少 发货人名称 | D1: 发货人名称 不应多于70个字符 | E1: 缺少 发货人地址 | F1: 发货人地址 不应多于140个字符 | G1: 缺少 发货人城市 | H1: 发货人城市 不应多于35个字符 | I1: 发货人国家编码 应为2个字符 | J1: 缺少 发货人联系电话 | K1: 发货人联系电话 不应多于60个字符 | L1: 缺少 收货人名称 | M1: 收货人名称 不应多于70个字符 | N1: 缺少 收货人地址 | O1: 收货人地址 不应多于140个字符 | P1: 缺少 收货人城市 | Q1: 收货人城市 不应多于35个字符 | R1: 收货人国家编码 应为2个字符 | S1: 缺少 收货人联系电话 | T1: 收货人联系电话 不应多于60个字符 | U1: 缺少 通知人名称 | V1: 通知人名称 不应多于70个字符 | W1: 缺少 通知人地址 | X1: 通知人地址 不应多于140个字符 | Y1: 缺少 通知人城市 | Z1: 通知人城市 不应多于35个字符 | AA1: 通知人国家编码 应为2个字符 | AB1: 缺少 通知人联系电话 | AC1: 通知人联系电话 不应多于60个字符 | AD1: 箱号 应为11个字符 | AE1: 尺寸箱型 错误 （请参照“箱型尺寸 ” 页） | AF1: 缺少 铅封号 | AG1: 铅封号 不应多于20个字符 | AH1: 件数 应为数字 | AI1: 包装代码 错误（请参照“包装代码”页） | AJ1: 货物毛重(kg) 应为数字 | AK1: 体积 (m3) 应为数字 | AL1: 唛头 不应多于90个字符 | AM1: 缺少 品名 | AN1: 品名 不应多于2000个字符 | AO1: 中转港 不应多于5个字符 | AP1: 缺少 目的港 | AQ1: 目的港 应为5个字符 | AR1: 付费方式代码 错误 （请参照“付款方式代码”页） | AS1: 运输条款代码 错误（请参照“运输条款”页） | AT1: 危险品类别 应为4个字符 | AU1: 危险品编码 应为10个字符 | AV1: 危险品联系人姓名 不应多于35个字符 | AW1: 通讯方式号码 不应多于20个字符 | AX1: Error message
A2: =OR(ISBLANK(data!B2), AND(B2:AW2)) -> FALSE | B2: =AND(LEFT(TRIM(data!B2), 4)="OOLU", ISNUMBER(RIGHT(TRIM(data!B2), LEN(TRIM(data!B2))-4)+0)) -> TRUE | C2: =LEN(data!C2)>0 -> TRUE | D2: =LEN(data!C2)<=70 -> TRUE | E2: =LEN(data!D2)>0 -> TRUE | F2: =LEN(data!D2)<=140 -> TRUE | G2: =LEN(data!E2)>0 -> FALSE | H2: =LEN(data!E2)<=35 -> TRUE | I2: =LEN(data!F2)=2 -> TRUE | J2: =LEN(data!G2)>0 -> TRUE | K2: =LEN(data!G2)<=60 -> TRUE | L2: =LEN(data!I2)>0 -> TRUE | M2: =LEN(data!I2)<=70 -> TRUE | N2: =LEN(data!J2)>0 -> TRUE | O2: =LEN(data!J2)<=140 -> TRUE | P2: =LEN(data!K2)>0 -> FALSE | Q2: =LEN(data!K2)<=35 -> TRUE | R2: =LEN(data!L2)=2 -> TRUE | S2: =LEN(data!M2)>0 -> TRUE | T2: =LEN(data!M2)<=60 -> TRUE | U2: =LEN(data!O2)>0 -> TRUE | V2: =LEN(data!O2)<=70 -> TRUE | W2: =LEN(data!P2)>0 -> TRUE | X2: =LEN(data!P2)<=140 -> TRUE | Y2: =LEN(data!Q2)>0 -> FALSE | Z2: =LEN(data!Q2)<=35 -> TRUE | AA2: =LEN(data!R2)=2 -> TRUE | AB2: =LEN(data!S2)>0 -> TRUE | AC2: =LEN(data!S2)<=60 -> TRUE | AD2: =LEN(data!U2)=11 -> TRUE | AE2: =AND(ISERROR(MATCH(data!V2, rule_mapping!$C$2:$C$325, 0))=FALSE, LEN(data!V2) <= 4) -> TRUE | AF2: =LEN(data!W2)>0 -> TRUE | AG2: =LEN(data!W2)<=20 -> TRUE | AH2: =IFERROR(ISNUMBER(data!X2), FALSE) -> TRUE | AI2: =IF(ISERROR(MATCH(data!Y2, rule_mapping!$D$2:$D$252, 0))=FALSE,TRUE, FALSE) -> TRUE | AJ2: =IFERROR(ISNUMBER(data!Z2), FALSE) -> TRUE | AK2: =IFERROR(ISNUMBER(data!AA2), FALSE) -> TRUE | AL2: =LEN(data!AB2)<=90 -> FALSE | AM2: =LEN(data!AC2)>0 -> TRUE | AN2: =LEN(data!AC2)<=2000 -> TRUE | AO2: =IF(LEN(data!AD2)=0,TRUE,IF(LEN(data!AD2)=5,TRUE,FALSE)) -> TRUE | AP2: =LEN(data!AE2)>0 -> TRUE | AQ2: =LEN(data!AE2)=5 -> TRUE | AR2: =ISERROR(MATCH(data!AF2, rule_mapping!$B$2:$B$3, 0))=FALSE -> TRUE | AS2: =ISERROR(MATCH(data!AG2, rule_mapping!$A$2:$A$8, 0))=FALSE -> TRUE | AT2: =LEN(data!AH2)<=4 -> TRUE | AU2: =LEN(data!AI2)<=10 -> TRUE | AV2: =LEN(data!AJ2)<=35 -> TRUE | AW2: =LEN(data!AK2)<=20 -> TRUE | AX2: =CONCATENATE(IF(NOT(B2), B$1 & CHAR(10), ""), IF(NOT(C2), C$1 & CHAR(10), ""), IF(NOT(D2), D$1 & CHAR(10), ""), IF(NOT(E2), E$1 & CHAR(10), ""), IF(NOT(F2), F$1 & CHAR(10), ""), IF(NOT(G2), G$1 & CHAR(10), ""), IF(NOT(H2), H$1 & CHAR(10), ""), IF(NOT(I2), I$1 & CHAR(10), ""), IF(NOT(J2), J$1 & CHAR(10), ""), IF(NOT(K2), K$1 & CHAR(10), ""), IF(NOT(L2), L$1 & CHAR(10), ""), IF(NOT(M2), M$1 & CHAR(10), ""), IF(NOT(N2), N$1 & CHAR(10), ""), IF(NOT(O2), O$1 & CHAR(10), ""), IF(NOT(P2), P$1 & CHAR(10), ""), IF(NOT(Q2), Q$1 & CHAR(10), ""), IF(NOT(R2), R$1 & CHAR(10), ""), IF(NOT(S2), S$1 & CHAR(10), ""), IF(NOT(T2), T$1 & CHAR(10), ""), IF(NOT(U2), U$1 & CHAR(10), ""), IF(NOT(V2), V$1 & CHAR(10), ""), IF(NOT(W2), W$1 & CHAR(10), ""), IF(NOT(X2), X$1 & CHAR(10), ""), IF(NOT(Y2), Y$1 & CHAR(10), ""), IF(NOT(Z2), Z$1 & CHAR(10), ""), IF(NOT(AA2), AA$1 & CHAR(10), ""), IF(NOT(AB2), AB$1 & CHAR(10), ""), IF(NOT(AC2), AC$1 & CHAR(10), ""), IF(NOT(AD2), AD$1 & CHAR(10), ""), IF(NOT(AE2), AE$1 & CHAR(10), ""), IF(NOT(AF2), AF$1 & CHAR(10), ""), IF(NOT(AG2), AG$1 & CHAR(10), ""), IF(NOT(AH2), AH$1 & CHAR(10), ""), IF(NOT(AI2), AI$1 & CHAR(10), ""), IF(NOT(AJ2), AJ$1 & CHAR(10), ""), IF(NOT(AK2), AK$1 & CHAR(10), ""), IF(NOT(AL2), AL$1 & CHAR(10), ""), IF(NOT(AM2), AM$1 & CHAR(10), ""), IF(NOT(AN2), AN$1 & CHAR(10), ""), IF(NOT(AO2), AO$1 & CHAR(10), ""), IF(NOT(AP2), AP$1 & CHAR(10), ""), IF(NOT(AQ2), AQ$1 & CHAR(10), ""), IF(NOT(AR2), AR$1 & CHAR(10), ""), IF(NOT(AS2), AS$1 & CHAR(10), ""), IF(NOT(AT2), AT$1 & CHAR(10), ""), IF(NOT(AU2), AU$1 & CHAR(10), ""), IF(NOT(AV2), AV$1 & CHAR(10), ""), IF(NOT(AW2), AW$1 & CHAR(10), "")) -> 缺少 发货人城市 缺少 收货人城市 缺少 通知人城市 唛头 不应多于90个字符
A3: =OR(ISBLANK(data!B3), AND(B3:AW3)) -> FALSE | B3: =AND(LEFT(TRIM(data!B3), 4)="OOLU", ISNUMBER(RIGHT(TRIM(data!B3), LEN(TRIM(data!B3))-4)+0)) -> TRUE | C3: =LEN(data!C3)>0 -> TRUE | D3: =LEN(data!C3)<=70 -> TRUE | E3: =LEN(data!D3)>0 -> TRUE | F3: =LEN(data!D3)<=140 -> TRUE | G3: =LEN(data!E3)>0 -> FALSE | H3: =LEN(data!E3)<=35 -> TRUE | I3: =LEN(data!F3)=2 -> TRUE | J3: =LEN(data!G3)>0 -> TRUE | K3: =LEN(data!G3)<=60 -> TRUE | L3: =LEN(data!I3)>0 -> TRUE | M3: =LEN(data!I3)<=70 -> TRUE | N3: =LEN(data!J3)>0 -> TRUE | O3: =LEN(data!J3)<=140 -> TRUE | P3: =LEN(data!K3)>0 -> FALSE | Q3: =LEN(data!K3)<=35 -> TRUE | R3: =LEN(data!L3)=2 -> TRUE | S3: =LEN(data!M3)>0 -> TRUE | T3: =LEN(data!M3)<=60 -> TRUE | U3: =LEN(data!O3)>0 -> TRUE | V3: =LEN(data!O3)<=70 -> TRUE | W3: =LEN(data!P3)>0 -> TRUE | X3: =LEN(data!P3)<=140 -> TRUE | Y3: =LEN(data!Q3)>0 -> FALSE | Z3: =LEN(data!Q3)<=35 -> TRUE | AA3: =LEN(data!R3)=2 -> TRUE | AB3: =LEN(data!S3)>0 -> TRUE | AC3: =LEN(data!S3)<=120 -> TRUE | AD3: =LEN(data!U3)=11 -> TRUE | AE3: =AND(ISERROR(MATCH(data!V3, rule_mapping!$C$2:$C$325, 0))=FALSE, LEN(data!V3) <= 4) -> TRUE | AF3: =LEN(data!W3)>0 -> TRUE | AG3: =LEN(data!W3)<=20 -> TRUE | AH3: =IFERROR(ISNUMBER(data!X3), FALSE) -> TRUE | AI3: =IF(ISERROR(MATCH(data!Y3, rule_mapping!$D$2:$D$252, 0))=FALSE,TRUE, FALSE) -> TRUE | AJ3: =IFERROR(ISNUMBER(data!Z3), FALSE) -> TRUE | AK3: =IFERROR(ISNUMBER(data!AA3), FALSE) -> TRUE | AL3: =LEN(data!AB3)<=90 -> FALSE | AM3: =LEN(data!AC3)>0 -> TRUE | AN3: =LEN(data!AC3)<=2000 -> TRUE | AO3: =IF(LEN(data!AD3)=0,TRUE,IF(LEN(data!AD3)=5,TRUE,FALSE)) -> TRUE | AP3: =LEN(data!AE3)>0 -> TRUE | AQ3: =LEN(data!AE3)=5 -> TRUE | AR3: =ISERROR(MATCH(data!AF3, rule_mapping!$B$2:$B$3, 0))=FALSE -> TRUE | AS3: =ISERROR(MATCH(data!AG3, rule_mapping!$A$2:$A$8, 0))=FALSE -> TRUE | AT3: =LEN(data!AH3)<=4 -> TRUE | AU3: =LEN(data!AI3)<=10 -> TRUE | AV3: =LEN(data!AJ3)<=35 -> TRUE | AW3: =LEN(data!AK3)<=20 -> TRUE | AX3: =CONCATENATE(IF(NOT(B3), B$1 & CHAR(10), ""), IF(NOT(C3), C$1 & CHAR(10), ""), IF(NOT(D3), D$1 & CHAR(10), ""), IF(NOT(E3), E$1 & CHAR(10), ""), IF(NOT(F3), F$1 & CHAR(10), ""), IF(NOT(G3), G$1 & CHAR(10), ""), IF(NOT(H3), H$1 & CHAR(10), ""), IF(NOT(I3), I$1 & CHAR(10), ""), IF(NOT(J3), J$1 & CHAR(10), ""), IF(NOT(K3), K$1 & CHAR(10), ""), IF(NOT(L3), L$1 & CHAR(10), ""), IF(NOT(M3), M$1 & CHAR(10), ""), IF(NOT(N3), N$1 & CHAR(10), ""), IF(NOT(O3), O$1 & CHAR(10), ""), IF(NOT(P3), P$1 & CHAR(10), ""), IF(NOT(Q3), Q$1 & CHAR(10), ""), IF(NOT(R3), R$1 & CHAR(10), ""), IF(NOT(S3), S$1 & CHAR(10), ""), IF(NOT(T3), T$1 & CHAR(10), ""), IF(NOT(U3), U$1 & CHAR(10), ""), IF(NOT(V3), V$1 & CHAR(10), ""), IF(NOT(W3), W$1 & CHAR(10), ""), IF(NOT(X3), X$1 & CHAR(10), ""), IF(NOT(Y3), Y$1 & CHAR(10), ""), IF(NOT(Z3), Z$1 & CHAR(10), ""), IF(NOT(AA3), AA$1 & CHAR(10), ""), IF(NOT(AB3), AB$1 & CHAR(10), ""), IF(NOT(AC3), AC$1 & CHAR(10), ""), IF(NOT(AD3), AD$1 & CHAR(10), ""), IF(NOT(AE3), AE$1 & CHAR(10), ""), IF(NOT(AF3), AF$1 & CHAR(10), ""), IF(NOT(AG3), AG$1 & CHAR(10), ""), IF(NOT(AH3), AH$1 & CHAR(10), ""), IF(NOT(AI3), AI$1 & CHAR(10), ""), IF(NOT(AJ3), AJ$1 & CHAR(10), ""), IF(NOT(AK3), AK$1 & CHAR(10), ""), IF(NOT(AL3), AL$1 & CHAR(10), ""), IF(NOT(AM3), AM$1 & CHAR(10), ""), IF(NOT(AN3), AN$1 & CHAR(10), ""), IF(NOT(AO3), AO$1 & CHAR(10), ""), IF(NOT(AP3), AP$1 & CHAR(10), ""), IF(NOT(AQ3), AQ$1 & CHAR(10), ""), IF(NOT(AR3), AR$1 & CHAR(10), ""), IF(NOT(AS3), AS$1 & CHAR(10), ""), IF(NOT(AT3), AT$1 & CHAR(10), ""), IF(NOT(AU3), AU$1 & CHAR(10), ""), IF(NOT(AV3), AV$1 & CHAR(10), ""), IF(NOT(AW3), AW$1 & CHAR(10), "")) -> 缺少 发货人城市 缺少 收货人城市 缺少 通知人城市 唛头 不应多于90个字符
A4: =OR(ISBLANK(data!B4), AND(B4:AW4)) -> FALSE | B4: =AND(LEFT(TRIM(data!B4), 4)="OOLU", ISNUMBER(RIGHT(TRIM(data!B4), LEN(TRIM(data!B4))-4)+0)) -> TRUE | C4: =LEN(data!C4)>0 -> TRUE | D4: =LEN(data!C4)<=70 -> TRUE | E4: =LEN(data!D4)>0 -> TRUE | F4: =LEN(data!D4)<=140 -> TRUE | G4: =LEN(data!E4)>0 -> FALSE | H4: =LEN(data!E4)<=35 -> TRUE | I4: =LEN(data!F4)=2 -> TRUE | J4: =LEN(data!G4)>0 -> TRUE | K4: =LEN(data!G4)<=60 -> TRUE | L4: =LEN(data!I4)>0 -> TRUE | M4: =LEN(data!I4)<=70 -> TRUE | N4: =LEN(data!J4)>0 -> TRUE | O4: =LEN(data!J4)<=140 -> TRUE | P4: =LEN(data!K4)>0 -> FALSE | Q4: =LEN(data!K4)<=35 -> TRUE | R4: =LEN(data!L4)=2 -> TRUE | S4: =LEN(data!M4)>0 -> TRUE | T4: =LEN(data!M4)<=60 -> TRUE | U4: =LEN(data!O4)>0 -> TRUE | V4: =LEN(data!O4)<=70 -> TRUE | W4: =LEN(data!P4)>0 -> TRUE | X4: =LEN(data!P4)<=140 -> TRUE | Y4: =LEN(data!Q4)>0 -> FALSE | Z4: =LEN(data!Q4)<=35 -> TRUE | AA4: =LEN(data!R4)=2 -> TRUE | AB4: =LEN(data!S4)>0 -> TRUE | AC4: =LEN(data!S4)<=120 -> TRUE | AD4: =LEN(data!U4)=11 -> TRUE | AE4: =AND(ISERROR(MATCH(data!V4, rule_mapping!$C$2:$C$325, 0))=FALSE, LEN(data!V4) <= 4) -> TRUE | AF4: =LEN(data!W4)>0 -> TRUE | AG4: =LEN(data!W4)<=20 -> TRUE | AH4: =IFERROR(ISNUMBER(data!X4), FALSE) -> TRUE | AI4: =IF(ISERROR(MATCH(data!Y4, rule_mapping!$D$2:$D$252, 0))=FALSE,TRUE, FALSE) -> TRUE | AJ4: =IFERROR(ISNUMBER(data!Z4), FALSE) -> TRUE | AK4: =IFERROR(ISNUMBER(data!AA4), FALSE) -> TRUE | AL4: =LEN(data!AB4)<=90 -> FALSE | AM4: =LEN(data!AC4)>0 -> TRUE | AN4: =LEN(data!AC4)<=2000 -> TRUE | AO4: =IF(LEN(data!AD4)=0,TRUE,IF(LEN(data!AD4)=5,TRUE,FALSE)) -> TRUE | AP4: =LEN(data!AE4)>0 -> TRUE | AQ4: =LEN(data!AE4)=5 -> TRUE | AR4: =ISERROR(MATCH(data!AF4, rule_mapping!$B$2:$B$3, 0))=FALSE -> TRUE | AS4: =ISERROR(MATCH(data!AG4, rule_mapping!$A$2:$A$8, 0))=FALSE -> TRUE | AT4: =LEN(data!AH4)<=4 -> TRUE | AU4: =LEN(data!AI4)<=10 -> TRUE | AV4: =LEN(data!AJ4)<=35 -> TRUE | AW4: =LEN(data!AK4)<=20 -> TRUE | AX4: =CONCATENATE(IF(NOT(B4), B$1 & CHAR(10), ""), IF(NOT(C4), C$1 & CHAR(10), ""), IF(NOT(D4), D$1 & CHAR(10), ""), IF(NOT(E4), E$1 & CHAR(10), ""), IF(NOT(F4), F$1 & CHAR(10), ""), IF(NOT(G4), G$1 & CHAR(10), ""), IF(NOT(H4), H$1 & CHAR(10), ""), IF(NOT(I4), I$1 & CHAR(10), ""), IF(NOT(J4), J$1 & CHAR(10), ""), IF(NOT(K4), K$1 & CHAR(10), ""), IF(NOT(L4), L$1 & CHAR(10), ""), IF(NOT(M4), M$1 & CHAR(10), ""), IF(NOT(N4), N$1 & CHAR(10), ""), IF(NOT(O4), O$1 & CHAR(10), ""), IF(NOT(P4), P$1 & CHAR(10), ""), IF(NOT(Q4), Q$1 & CHAR(10), ""), IF(NOT(R4), R$1 & CHAR(10), ""), IF(NOT(S4), S$1 & CHAR(10), ""), IF(NOT(T4), T$1 & CHAR(10), ""), IF(NOT(U4), U$1 & CHAR(10), ""), IF(NOT(V4), V$1 & CHAR(10), ""), IF(NOT(W4), W$1 & CHAR(10), ""), IF(NOT(X4), X$1 & CHAR(10), ""), IF(NOT(Y4), Y$1 & CHAR(10), ""), IF(NOT(Z4), Z$1 & CHAR(10), ""), IF(NOT(AA4), AA$1 & CHAR(10), ""), IF(NOT(AB4), AB$1 & CHAR(10), ""), IF(NOT(AC4), AC$1 & CHAR(10), ""), IF(NOT(AD4), AD$1 & CHAR(10), ""), IF(NOT(AE4), AE$1 & CHAR(10), ""), IF(NOT(AF4), AF$1 & CHAR(10), ""), IF(NOT(AG4), AG$1 & CHAR(10), ""), IF(NOT(AH4), AH$1 & CHAR(10), ""), IF(NOT(AI4), AI$1 & CHAR(10), ""), IF(NOT(AJ4), AJ$1 & CHAR(10), ""), IF(NOT(AK4), AK$1 & CHAR(10), ""), IF(NOT(AL4), AL$1 & CHAR(10), ""), IF(NOT(AM4), AM$1 & CHAR(10), ""), IF(NOT(AN4), AN$1 & CHAR(10), ""), IF(NOT(AO4), AO$1 & CHAR(10), ""), IF(NOT(AP4), AP$1 & CHAR(10), ""), IF(NOT(AQ4), AQ$1 & CHAR(10), ""), IF(NOT(AR4), AR$1 & CHAR(10), ""), IF(NOT(AS4), AS$1 & CHAR(10), ""), IF(NOT(AT4), AT$1 & CHAR(10), ""), IF(NOT(AU4), AU$1 & CHAR(10), ""), IF(NOT(AV4), AV$1 & CHAR(10), ""), IF(NOT(AW4), AW$1 & CHAR(10), "")) -> 缺少 发货人城市 缺少 收货人城市 缺少 通知人城市 唛头 不应多于90个字符
A5: =OR(ISBLANK(data!B5), AND(B5:AW5)) -> TRUE | B5: =AND(LEFT(TRIM(data!B5), 4)="OOLU", ISNUMBER(RIGHT(TRIM(data!B5), LEN(TRIM(data!B5))-4)+0)) -> FALSE | C5: =LEN(data!C5)>0 -> FALSE | D5: =LEN(data!C5)<=70 -> TRUE | E5: =LEN(data!D5)>0 -> FALSE | F5: =LEN(data!D5)<=140 -> TRUE | G5: =LEN(data!E5)>0 -> FALSE | H5: =LEN(data!E5)<=35 -> TRUE | I5: =LEN(data!F5)=2 -> FALSE | J5: =LEN(data!G5)>0 -> FALSE | K5: =LEN(data!G5)<=60 -> TRUE | L5: =LEN(data!I5)>0 -> FALSE | M5: =LEN(data!I5)<=70 -> TRUE | N5: =LEN(data!J5)>0 -> FALSE | O5: =LEN(data!J5)<=140 -> TRUE | P5: =LEN(data!K5)>0 -> FALSE | Q5: =LEN(data!K5)<=35 -> TRUE | R5: =LEN(data!L5)=2 -> FALSE | S5: =LEN(data!M5)>0 -> FALSE | T5: =LEN(data!M5)<=60 -> TRUE | U5: =LEN(data!O5)>0 -> FALSE | V5: =LEN(data!O5)<=70 -> TRUE | W5: =LEN(data!P5)>0 -> FALSE | X5: =LEN(data!P5)<=140 -> TRUE | Y5: =LEN(data!Q5)>0 -> FALSE | Z5: =LEN(data!Q5)<=35 -> TRUE | AA5: =LEN(data!R5)=2 -> FALSE | AB5: =LEN(data!S5)>0 -> FALSE | AC5: =LEN(data!S5)<=120 -> TRUE | AD5: =LEN(data!U5)=11 -> FALSE | AE5: =AND(ISERROR(MATCH(data!V5, rule_mapping!$C$2:$C$325, 0))=FALSE, LEN(data!V5) <= 4) -> FALSE | AF5: =LEN(data!W5)>0 -> FALSE | AG5: =LEN(data!W5)<=20 -> TRUE | AH5: =IFERROR(ISNUMBER(data!X5), FALSE) -> FALSE | AI5: =IF(ISERROR(MATCH(data!Y5, rule_mapping!$D$2:$D$252, 0))=FALSE,TRUE, FALSE) -> FALSE | AJ5: =IFERROR(ISNUMBER(data!Z5), FALSE) -> FALSE | AK5: =IFERROR(ISNUMBER(data!AA5), FALSE) -> FALSE | AL5: =LEN(data!AB5)<=90 -> TRUE | AM5: =LEN(data!AC5)>0 -> FALSE | AN5: =LEN(data!AC5)<=2000 -> TRUE | AO5: =IF(LEN(data!AD5)=0,TRUE,IF(LEN(data!AD5)=5,TRUE,FALSE)) -> TRUE | AP5: =LEN(data!AE5)>0 -> FALSE | AQ5: =LEN(data!AE5)=5 -> FALSE | AR5: =ISERROR(MATCH(data!AF5, rule_mapping!$B$2:$B$3, 0))=FALSE -> FALSE | AS5: =ISERROR(MATCH(data!AG5, rule_mapping!$A$2:$A$8, 0))=FALSE -> FALSE | AT5: =LEN(data!AH5)<=4 -> TRUE | AU5: =LEN(data!AI5)<=10 -> TRUE | AV5: =LEN(data!AJ5)<=35 -> TRUE | AW5: =LEN(data!AK5)<=20 -> TRUE | AX5: =CONCATENATE(IF(NOT(B5), B$1 & CHAR(10), ""), IF(NOT(C5), C$1 & CHAR(10), ""), IF(NOT(D5), D$1 & CHAR(10), ""), IF(NOT(E5), E$1 & CHAR(10), ""), IF(NOT(F5), F$1 & CHAR(10), ""), IF(NOT(G5), G$1 & CHAR(10), ""), IF(NOT(H5), H$1 & CHAR(10), ""), IF(NOT(I5), I$1 & CHAR(10), ""), IF(NOT(J5), J$1 & CHAR(10), ""), IF(NOT(K5), K$1 & CHAR(10), ""), IF(NOT(L5), L$1 & CHAR(10), ""), IF(NOT(M5), M$1 & CHAR(10), ""), IF(NOT(N5), N$1 & CHAR(10), ""), IF(NOT(O5), O$1 & CHAR(10), ""), IF(NOT(P5), P$1 & CHAR(10), ""), IF(NOT(Q5), Q$1 & CHAR(10), ""), IF(NOT(R5), R$1 & CHAR(10), ""), IF(NOT(S5), S$1 & CHAR(10), ""), IF(NOT(T5), T$1 & CHAR(10), ""), IF(NOT(U5), U$1 & CHAR(10), ""), IF(NOT(V5), V$1 & CHAR(10), ""), IF(NOT(W5), W$1 & CHAR(10), ""), IF(NOT(X5), X$1 & CHAR(10), ""), IF(NOT(Y5), Y$1 & CHAR(10), ""), IF(NOT(Z5), Z$1 & CHAR(10), ""), IF(NOT(AA5), AA$1 & CHAR(10), ""), IF(NOT(AB5), AB$1 & CHAR(10), ""), IF(NOT(AC5), AC$1 & CHAR(10), ""), IF(NOT(AD5), AD$1 & CHAR(10), ""), IF(NOT(AE5), AE$1 & CHAR(10), ""), IF(NOT(AF5), AF$1 & CHAR(10), ""), IF(NOT(AG5), AG$1 & CHAR(10), ""), IF(NOT(AH5), AH$1 & CHAR(10), ""), IF(NOT(AI5), AI$1 & CHAR(10), ""), IF(NOT(AJ5), AJ$1 & CHAR(10), ""), IF(NOT(AK5), AK$1 & CHAR(10), ""), IF(NOT(AL5), AL$1 & CHAR(10), ""), IF(NOT(AM5), AM$1 & CHAR(10), ""), IF(NOT(AN5), AN$1 & CHAR(10), ""), IF(NOT(AO5), AO$1 & CHAR(10), ""), IF(NOT(AP5), AP$1 & CHAR(10), ""), IF(NOT(AQ5), AQ$1 & CHAR(10), ""), IF(NOT(AR5), AR$1 & CHAR(10), ""), IF(NOT(AS5), AS$1 & CHAR(10), ""), IF(NOT(AT5), AT$1 & CHAR(10), ""), IF(NOT(AU5), AU$1 & CHAR(10), ""), IF(NOT(AV5), AV$1 & CHAR(10), ""), IF(NOT(AW5), AW$1 & CHAR(10), "")) -> 关单号 应以OOLU开头 缺少 发货人名称 缺少 发货人地址 缺少 发货人城市 发货人国家编码 应为2个字符 缺少 发货人联系电话 缺少 收货人名称 缺少 收货人地址 缺少 收货人城市 收货人国家编码 应为2个字符 缺少 收货人联系电话 缺少 通知人名称 缺少 通知人地址 缺少 通知人城市 通知人国家编码 应为2个字符 缺少 通知人联系电话 箱号 应为11个字符 尺寸箱型 错误 （请参照“箱型尺寸 ” 页） 缺少 铅封号 件数 应为数字 包装代码 错误（请参照“包装代码”页） 货物毛重(kg) 应为数字 体积 (m3) 应为数字 缺少 品名 缺少 目的港 目的港 应为5个字符 付费方式代码 错误 （请参照“付款方式代码”页） 运输条款代码 错误（请参照“运输条款”页）
A6: =OR(ISBLANK(data!B6), AND(B6:AW6)) -> TRUE | B6: =AND(LEFT(TRIM(data!B6), 4)="OOLU", ISNUMBER(RIGHT(TRIM(data!B6), LEN(TRIM(data!B6))-4)+0)) -> FALSE | C6: =LEN(data!C6)>0 -> FALSE | D6: =LEN(data!C6)<=70 -> TRUE | E6: =LEN(data!D6)>0 -> FALSE | F6: =LEN(data!D6)<=140 -> TRUE | G6: =LEN(data!E6)>0 -> FALSE | H6: =LEN(data!E6)<=35 -> TRUE | I6: =LEN(data!F6)=2 -> FALSE | J6: =LEN(data!G6)>0 -> FALSE | K6: =LEN(data!G6)<=60 -> TRUE | L6: =LEN(data!I6)>0 -> FALSE | M6: =LEN(data!I6)<=70 -> TRUE | N6: =LEN(data!J6)>0 -> FALSE | O6: =LEN(data!J6)<=140 -> TRUE | P6: =LEN(data!K6)>0 -> FALSE | Q6: =LEN(data!K6)<=35 -> TRUE | R6: =LEN(data!L6)=2 -> FALSE | S6: =LEN(data!M6)>0 -> FALSE | T6: =LEN(data!M6)<=60 -> TRUE | U6: =LEN(data!O6)>0 -> FALSE | V6: =LEN(data!O6)<=70 -> TRUE | W6: =LEN(data!P6)>0 -> FALSE | X6: =LEN(data!P6)<=140 -> TRUE | Y6: =LEN(data!Q6)>0 -> FALSE | Z6: =LEN(data!Q6)<=35 -> TRUE | AA6: =LEN(data!R6)=2 -> FALSE | AB6: =LEN(data!S6)>0 -> FALSE | AC6: =LEN(data!S6)<=120 -> TRUE | AD6: =LEN(data!U6)=11 -> FALSE | AE6: =AND(ISERROR(MATCH(data!V6, rule_mapping!$C$2:$C$325, 0))=FALSE, LEN(data!V6) <= 4) -> FALSE | AF6: =LEN(data!W6)>0 -> FALSE | AG6: =LEN(data!W6)<=20 -> TRUE | AH6: =IFERROR(ISNUMBER(data!X6), FALSE) -> FALSE | AI6: =IF(ISERROR(MATCH(data!Y6, rule_mapping!$D$2:$D$252, 0))=FALSE,TRUE, FALSE) -> FALSE | AJ6: =IFERROR(ISNUMBER(data!Z6), FALSE) -> FALSE | AK6: =IFERROR(ISNUMBER(data!AA6), FALSE) -> FALSE | AL6: =LEN(data!AB6)<=90 -> TRUE | AM6: =LEN(data!AC6)>0 -> FALSE | AN6: =LEN(data!AC6)<=2000 -> TRUE | AO6: =IF(LEN(data!AD6)=0,TRUE,IF(LEN(data!AD6)=5,TRUE,FALSE)) -> TRUE | AP6: =LEN(data!AE6)>0 -> FALSE | AQ6: =LEN(data!AE6)=5 -> FALSE | AR6: =ISERROR(MATCH(data!AF6, rule_mapping!$B$2:$B$3, 0))=FALSE -> FALSE | AS6: =ISERROR(MATCH(data!AG6, rule_mapping!$A$2:$A$8, 0))=FALSE -> FALSE | AT6: =LEN(data!AH6)<=4 -> TRUE | AU6: =LEN(data!AI6)<=10 -> TRUE | AV6: =LEN(data!AJ6)<=35 -> TRUE | AW6: =LEN(data!AK6)<=20 -> TRUE | AX6: =CONCATENATE(IF(NOT(B6), B$1 & CHAR(10), ""), IF(NOT(C6), C$1 & CHAR(10), ""), IF(NOT(D6), D$1 & CHAR(10), ""), IF(NOT(E6), E$1 & CHAR(10), ""), IF(NOT(F6), F$1 & CHAR(10), ""), IF(NOT(G6), G$1 & CHAR(10), ""), IF(NOT(H6), H$1 & CHAR(10), ""), IF(NOT(I6), I$1 & CHAR(10), ""), IF(NOT(J6), J$1 & CHAR(10), ""), IF(NOT(K6), K$1 & CHAR(10), ""), IF(NOT(L6), L$1 & CHAR(10), ""), IF(NOT(M6), M$1 & CHAR(10), ""), IF(NOT(N6), N$1 & CHAR(10), ""), IF(NOT(O6), O$1 & CHAR(10), ""), IF(NOT(P6), P$1 & CHAR(10), ""), IF(NOT(Q6), Q$1 & CHAR(10), ""), IF(NOT(R6), R$1 & CHAR(10), ""), IF(NOT(S6), S$1 & CHAR(10), ""), IF(NOT(T6), T$1 & CHAR(10), ""), IF(NOT(U6), U$1 & CHAR(10), ""), IF(NOT(V6), V$1 & CHAR(10), ""), IF(NOT(W6), W$1 & CHAR(10), ""), IF(NOT(X6), X$1 & CHAR(10), ""), IF(NOT(Y6), Y$1 & CHAR(10), ""), IF(NOT(Z6), Z$1 & CHAR(10), ""), IF(NOT(AA6), AA$1 & CHAR(10), ""), IF(NOT(AB6), AB$1 & CHAR(10), ""), IF(NOT(AC6), AC$1 & CHAR(10), ""), IF(NOT(AD6), AD$1 & CHAR(10), ""), IF(NOT(AE6), AE$1 & CHAR(10), ""), IF(NOT(AF6), AF$1 & CHAR(10), ""), IF(NOT(AG6), AG$1 & CHAR(10), ""), IF(NOT(AH6), AH$1 & CHAR(10), ""), IF(NOT(AI6), AI$1 & CHAR(10), ""), IF(NOT(AJ6), AJ$1 & CHAR(10), ""), IF(NOT(AK6), AK$1 & CHAR(10), ""), IF(NOT(AL6), AL$1 & CHAR(10), ""), IF(NOT(AM6), AM$1 & CHAR(10), ""), IF(NOT(AN6), AN$1 & CHAR(10), ""), IF(NOT(AO6), AO$1 & CHAR(10), ""), IF(NOT(AP6), AP$1 & CHAR(10), ""), IF(NOT(AQ6), AQ$1 & CHAR(10), ""), IF(NOT(AR6), AR$1 & CHAR(10), ""), IF(NOT(AS6), AS$1 & CHAR(10), ""), IF(NOT(AT6), AT$1 & CHAR(10), ""), IF(NOT(AU6), AU$1 & CHAR(10), ""), IF(NOT(AV6), AV$1 & CHAR(10), ""), IF(NOT(AW6), AW$1 & CHAR(10), "")) -> 关单号 应以OOLU开头 缺少 发货人名称 缺少 发货人地址 缺少 发货人城市 发货人国家编码 应为2个字符 缺少 发货人联系电话 缺少 收货人名称 缺少 收货人地址 缺少 收货人城市 收货人国家编码 应为2个字符 缺少 收货人联系电话 缺少 通知人名称 缺少 通知人地址 缺少 通知人城市 通知人国家编码 应为2个字符 缺少 通知人联系电话 箱号 应为11个字符 尺寸箱型 错误 （请参照“箱型尺寸 ” 页） 缺少 铅封号 件数 应为数字 包装代码 错误（请参照“包装代码”页） 货物毛重(kg) 应为数字 体积 (m3) 应为数字 缺少 品名 缺少 目的港 目的港 应为5个字符 付费方式代码 错误 （请参照“付款方式代码”页） 运输条款代码 错误（请参照“运输条款”页）
A7: =OR(ISBLANK(data!B7), AND(B7:AW7)) -> TRUE | B7: =AND(LEFT(TRIM(data!B7), 4)="OOLU", ISNUMBER(RIGHT(TRIM(data!B7), LEN(TRIM(data!B7))-4)+0)) -> FALSE | C7: =LEN(data!C7)>0 -> FALSE | D7: =LEN(data!C7)<=70 -> TRUE | E7: =LEN(data!D7)>0 -> FALSE | F7: =LEN(data!D7)<=140 -> TRUE | G7: =LEN(data!E7)>0 -> FALSE | H7: =LEN(data!E7)<=35 -> TRUE | I7: =LEN(data!F7)=2 -> FALSE | J7: =LEN(data!G7)>0 -> FALSE | K7: =LEN(data!G7)<=60 -> TRUE | L7: =LEN(data!I7)>0 -> FALSE | M7: =LEN(data!I7)<=70 -> TRUE | N7: =LEN(data!J7)>0 -> FALSE | O7: =LEN(data!J7)<=140 -> TRUE | P7: =LEN(data!K7)>0 -> FALSE | Q7: =LEN(data!K7)<=35 -> TRUE | R7: =LEN(data!L7)=2 -> FALSE | S7: =LEN(data!M7)>0 -> FALSE | T7: =LEN(data!M7)<=60 -> TRUE | U7: =LEN(data!O7)>0 -> FALSE | V7: =LEN(data!O7)<=70 -> TRUE | W7: =LEN(data!P7)>0 -> FALSE | X7: =LEN(data!P7)<=140 -> TRUE | Y7: =LEN(data!Q7)>0 -> FALSE | Z7: =LEN(data!Q7)<=35 -> TRUE | AA7: =LEN(data!R7)=2 -> FALSE | AB7: =LEN(data!S7)>0 -> FALSE | AC7: =LEN(data!S7)<=120 -> TRUE | AD7: =LEN(data!U7)=11 -> FALSE | AE7: =AND(ISERROR(MATCH(data!V7, rule_mapping!$C$2:$C$325, 0))=FALSE, LEN(data!V7) <= 4) -> FALSE | AF7: =LEN(data!W7)>0 -> FALSE | AG7: =LEN(data!W7)<=20 -> TRUE | AH7: =IFERROR(ISNUMBER(data!X7), FALSE) -> FALSE | AI7: =IF(ISERROR(MATCH(data!Y7, rule_mapping!$D$2:$D$252, 0))=FALSE,TRUE, FALSE) -> FALSE | AJ7: =IFERROR(ISNUMBER(data!Z7), FALSE) -> FALSE | AK7: =IFERROR(ISNUMBER(data!AA7), FALSE) -> FALSE | AL7: =LEN(data!AB7)<=90 -> TRUE | AM7: =LEN(data!AC7)>0 -> FALSE | AN7: =LEN(data!AC7)<=2000 -> TRUE | AO7: =IF(LEN(data!AD7)=0,TRUE,IF(LEN(data!AD7)=5,TRUE,FALSE)) -> TRUE | AP7: =LEN(data!AE7)>0 -> FALSE | AQ7: =LEN(data!AE7)=5 -> FALSE | AR7: =ISERROR(MATCH(data!AF7, rule_mapping!$B$2:$B$3, 0))=FALSE -> FALSE | AS7: =ISERROR(MATCH(data!AG7, rule_mapping!$A$2:$A$8, 0))=FALSE -> FALSE | AT7: =LEN(data!AH7)<=4 -> TRUE | AU7: =LEN(data!AI7)<=10 -> TRUE | AV7: =LEN(data!AJ7)<=35 -> TRUE | AW7: =LEN(data!AK7)<=20 -> TRUE | AX7: =CONCATENATE(IF(NOT(B7), B$1 & CHAR(10), ""), IF(NOT(C7), C$1 & CHAR(10), ""), IF(NOT(D7), D$1 & CHAR(10), ""), IF(NOT(E7), E$1 & CHAR(10), ""), IF(NOT(F7), F$1 & CHAR(10), ""), IF(NOT(G7), G$1 & CHAR(10), ""), IF(NOT(H7), H$1 & CHAR(10), ""), IF(NOT(I7), I$1 & CHAR(10), ""), IF(NOT(J7), J$1 & CHAR(10), ""), IF(NOT(K7), K$1 & CHAR(10), ""), IF(NOT(L7), L$1 & CHAR(10), ""), IF(NOT(M7), M$1 & CHAR(10), ""), IF(NOT(N7), N$1 & CHAR(10), ""), IF(NOT(O7), O$1 & CHAR(10), ""), IF(NOT(P7), P$1 & CHAR(10), ""), IF(NOT(Q7), Q$1 & CHAR(10), ""), IF(NOT(R7), R$1 & CHAR(10), ""), IF(NOT(S7), S$1 & CHAR(10), ""), IF(NOT(T7), T$1 & CHAR(10), ""), IF(NOT(U7), U$1 & CHAR(10), ""), IF(NOT(V7), V$1 & CHAR(10), ""), IF(NOT(W7), W$1 & CHAR(10), ""), IF(NOT(X7), X$1 & CHAR(10), ""), IF(NOT(Y7), Y$1 & CHAR(10), ""), IF(NOT(Z7), Z$1 & CHAR(10), ""), IF(NOT(AA7), AA$1 & CHAR(10), ""), IF(NOT(AB7), AB$1 & CHAR(10), ""), IF(NOT(AC7), AC$1 & CHAR(10), ""), IF(NOT(AD7), AD$1 & CHAR(10), ""), IF(NOT(AE7), AE$1 & CHAR(10), ""), IF(NOT(AF7), AF$1 & CHAR(10), ""), IF(NOT(AG7), AG$1 & CHAR(10), ""), IF(NOT(AH7), AH$1 & CHAR(10), ""), IF(NOT(AI7), AI$1 & CHAR(10), ""), IF(NOT(AJ7), AJ$1 & CHAR(10), ""), IF(NOT(AK7), AK$1 & CHAR(10), ""), IF(NOT(AL7), AL$1 & CHAR(10), ""), IF(NOT(AM7), AM$1 & CHAR(10), ""), IF(NOT(AN7), AN$1 & CHAR(10), ""), IF(NOT(AO7), AO$1 & CHAR(10), ""), IF(NOT(AP7), AP$1 & CHAR(10), ""), IF(NOT(AQ7), AQ$1 & CHAR(10), ""), IF(NOT(AR7), AR$1 & CHAR(10), ""), IF(NOT(AS7), AS$1 & CHAR(10), ""), IF(NOT(AT7), AT$1 & CHAR(10), ""), IF(NOT(AU7), AU$1 & CHAR(10), ""), IF(NOT(AV7), AV$1 & CHAR(10), ""), IF(NOT(AW7), AW$1 & CHAR(10), "")) -> 关单号 应以OOLU开头 缺少 发货人名称 缺少 发货人地址 缺少 发货人城市 发货人国家编码 应为2个字符 缺少 发货人联系电话 缺少 收货人名称 缺少 收货人地址 缺少 收货人城市 收货人国家编码 应为2个字符 缺少 收货人联系电话 缺少 通知人名称 缺少 通知人地址 缺少 通知人城市 通知人国家编码 应为2个字符 缺少 通知人联系电话 箱号 应为11个字符 尺寸箱型 错误 （请参照“箱型尺寸 ” 页） 缺少 铅封号 件数 应为数字 包装代码 错误（请参照“包装代码”页） 货物毛重(kg) 应为数字 体积 (m3) 应为数字 缺少 品名 缺少 目的港 目的港 应为5个字符 付费方式代码 错误 （请参照“付款方式代码”页） 运输条款代码 错误（请参照“运输条款”页）
A8: =OR(ISBLANK(data!B8), AND(B8:AW8)) -> TRUE | B8: =AND(LEFT(TRIM(data!B8), 4)="OOLU", ISNUMBER(RIGHT(TRIM(data!B8), LEN(TRIM(data!B8))-4)+0)) -> FALSE | C8: =LEN(data!C8)>0 -> FALSE | D8: =LEN(data!C8)<=70 -> TRUE | E8: =LEN(data!D8)>0 -> FALSE | F8: =LEN(data!D8)<=140 -> TRUE | G8: =LEN(data!E8)>0 -> FALSE | H8: =LEN(data!E8)<=35 -> TRUE | I8: =LEN(data!F8)=2 -> FALSE | J8: =LEN(data!G8)>0 -> FALSE | K8: =LEN(data!G8)<=60 -> TRUE | L8: =LEN(data!I8)>0 -> FALSE | M8: =LEN(data!I8)<=70 -> TRUE | N8: =LEN(data!J8)>0 -> FALSE | O8: =LEN(data!J8)<=140 -> TRUE | P8: =LEN(data!K8)>0 -> FALSE | Q8: =LEN(data!K8)<=35 -> TRUE | R8: =LEN(data!L8)=2 -> FALSE | S8: =LEN(data!M8)>0 -> FALSE | T8: =LEN(data!M8)<=60 -> TRUE | U8: =LEN(data!O8)>0 -> FALSE | V8: =LEN(data!O8)<=70 -> TRUE | W8: =LEN(data!P8)>0 -> FALSE | X8: =LEN(data!P8)<=140 -> TRUE | Y8: =LEN(data!Q8)>0 -> FALSE | Z8: =LEN(data!Q8)<=35 -> TRUE | AA8: =LEN(data!R8)=2 -> FALSE | AB8: =LEN(data!S8)>0 -> FALSE | AC8: =LEN(data!S8)<=120 -> TRUE | AD8: =LEN(data!U8)=11 -> FALSE | AE8: =AND(ISERROR(MATCH(data!V8, rule_mapping!$C$2:$C$325, 0))=FALSE, LEN(data!V8) <= 4) -> FALSE | AF8: =LEN(data!W8)>0 -> FALSE | AG8: =LEN(data!W8)<=20 -> TRUE | AH8: =IFERROR(ISNUMBER(data!X8), FALSE) -> FALSE | AI8: =IF(ISERROR(MATCH(data!Y8, rule_mapping!$D$2:$D$252, 0))=FALSE,TRUE, FALSE) -> FALSE | AJ8: =IFERROR(ISNUMBER(data!Z8), FALSE) -> FALSE | AK8: =IFERROR(ISNUMBER(data!AA8), FALSE) -> FALSE | AL8: =LEN(data!AB8)<=90 -> TRUE | AM8: =LEN(data!AC8)>0 -> FALSE | AN8: =LEN(data!AC8)<=2000 -> TRUE | AO8: =IF(LEN(data!AD8)=0,TRUE,IF(LEN(data!AD8)=5,TRUE,FALSE)) -> TRUE | AP8: =LEN(data!AE8)>0 -> FALSE | AQ8: =LEN(data!AE8)=5 -> FALSE | AR8: =ISERROR(MATCH(data!AF8, rule_mapping!$B$2:$B$3, 0))=FALSE -> FALSE | AS8: =ISERROR(MATCH(data!AG8, rule_mapping!$A$2:$A$8, 0))=FALSE -> FALSE | AT8: =LEN(data!AH8)<=4 -> TRUE | AU8: =LEN(data!AI8)<=10 -> TRUE | AV8: =LEN(data!AJ8)<=35 -> TRUE | AW8: =LEN(data!AK8)<=20 -> TRUE | AX8: =CONCATENATE(IF(NOT(B8), B$1 & CHAR(10), ""), IF(NOT(C8), C$1 & CHAR(10), ""), IF(NOT(D8), D$1 & CHAR(10), ""), IF(NOT(E8), E$1 & CHAR(10), ""), IF(NOT(F8), F$1 & CHAR(10), ""), IF(NOT(G8), G$1 & CHAR(10), ""), IF(NOT(H8), H$1 & CHAR(10), ""), IF(NOT(I8), I$1 & CHAR(10), ""), IF(NOT(J8), J$1 & CHAR(10), ""), IF(NOT(K8), K$1 & CHAR(10), ""), IF(NOT(L8), L$1 & CHAR(10), ""), IF(NOT(M8), M$1 & CHAR(10), ""), IF(NOT(N8), N$1 & CHAR(10), ""), IF(NOT(O8), O$1 & CHAR(10), ""), IF(NOT(P8), P$1 & CHAR(10), ""), IF(NOT(Q8), Q$1 & CHAR(10), ""), IF(NOT(R8), R$1 & CHAR(10), ""), IF(NOT(S8), S$1 & CHAR(10), ""), IF(NOT(T8), T$1 & CHAR(10), ""), IF(NOT(U8), U$1 & CHAR(10), ""), IF(NOT(V8), V$1 & CHAR(10), ""), IF(NOT(W8), W$1 & CHAR(10), ""), IF(NOT(X8), X$1 & CHAR(10), ""), IF(NOT(Y8), Y$1 & CHAR(10), ""), IF(NOT(Z8), Z$1 & CHAR(10), ""), IF(NOT(AA8), AA$1 & CHAR(10), ""), IF(NOT(AB8), AB$1 & CHAR(10), ""), IF(NOT(AC8), AC$1 & CHAR(10), ""), IF(NOT(AD8), AD$1 & CHAR(10), ""), IF(NOT(AE8), AE$1 & CHAR(10), ""), IF(NOT(AF8), AF$1 & CHAR(10), ""), IF(NOT(AG8), AG$1 & CHAR(10), ""), IF(NOT(AH8), AH$1 & CHAR(10), ""), IF(NOT(AI8), AI$1 & CHAR(10), ""), IF(NOT(AJ8), AJ$1 & CHAR(10), ""), IF(NOT(AK8), AK$1 & CHAR(10), ""), IF(NOT(AL8), AL$1 & CHAR(10), ""), IF(NOT(AM8), AM$1 & CHAR(10), ""), IF(NOT(AN8), AN$1 & CHAR(10), ""), IF(NOT(AO8), AO$1 & CHAR(10), ""), IF(NOT(AP8), AP$1 & CHAR(10), ""), IF(NOT(AQ8), AQ$1 & CHAR(10), ""), IF(NOT(AR8), AR$1 & CHAR(10), ""), IF(NOT(AS8), AS$1 & CHAR(10), ""), IF(NOT(AT8), AT$1 & CHAR(10), ""), IF(NOT(AU8), AU$1 & CHAR(10), ""), IF(NOT(AV8), AV$1 & CHAR(10), ""), IF(NOT(AW8), AW$1 & CHAR(10), "")) -> 关单号 应以OOLU开头 缺少 发货人名称 缺少 发货人地址 缺少 发货人城市 发货人国家编码 应为2个字符 缺少 发货人联系电话 缺少 收货人名称 缺少 收货人地址 缺少 收货人城市 收货人国家编码 应为2个字符 缺少 收货人联系电话 缺少 通知人名称 缺少 通知人地址 缺少 通知人城市 通知人国家编码 应为2个字符 缺少 通知人联系电话 箱号 应为11个字符 尺寸箱型 错误 （请参照“箱型尺寸 ” 页） 缺少 铅封号 件数 应为数字 包装代码 错误（请参照“包装代码”页） 货物毛重(kg) 应为数字 体积 (m3) 应为数字 缺少 品名 缺少 目的港 目的港 应为5个字符 付费方式代码 错误 （请参照“付款方式代码”页） 运输条款代码 错误（请参照“运输条款”页）
A9: =OR(ISBLANK(data!B9), AND(B9:AW9)) -> TRUE | B9: =AND(LEFT(TRIM(data!B9), 4)="OOLU", ISNUMBER(RIGHT(TRIM(data!B9), LEN(TRIM(data!B9))-4)+0)) -> FALSE | C9: =LEN(data!C9)>0 -> FALSE | D9: =LEN(data!C9)<=70 -> TRUE | E9: =LEN(data!D9)>0 -> FALSE | F9: =LEN(data!D9)<=140 -> TRUE | G9: =LEN(data!E9)>0 -> FALSE | H9: =LEN(data!E9)<=35 -> TRUE | I9: =LEN(data!F9)=2 -> FALSE | J9: =LEN(data!G9)>0 -> FALSE | K9: =LEN(data!G9)<=60 -> TRUE | L9: =LEN(data!I9)>0 -> FALSE | M9: =LEN(data!I9)<=70 -> TRUE | N9: =LEN(data!J9)>0 -> FALSE | O9: =LEN(data!J9)<=140 -> TRUE | P9: =LEN(data!K9)>0 -> FALSE | Q9: =LEN(data!K9)<=35 -> TRUE | R9: =LEN(data!L9)=2 -> FALSE | S9: =LEN(data!M9)>0 -> FALSE | T9: =LEN(data!M9)<=60 -> TRUE | U9: =LEN(data!O9)>0 -> FALSE | V9: =LEN(data!O9)<=70 -> TRUE | W9: =LEN(data!P9)>0 -> FALSE | X9: =LEN(data!P9)<=140 -> TRUE | Y9: =LEN(data!Q9)>0 -> FALSE | Z9: =LEN(data!Q9)<=35 -> TRUE | AA9: =LEN(data!R9)=2 -> FALSE | AB9: =LEN(data!S9)>0 -> FALSE | AC9: =LEN(data!S9)<=120 -> TRUE | AD9: =LEN(data!U9)=11 -> FALSE | AE9: =AND(ISERROR(MATCH(data!V9, rule_mapping!$C$2:$C$325, 0))=FALSE, LEN(data!V9) <= 4) -> FALSE | AF9: =LEN(data!W9)>0 -> FALSE | AG9: =LEN(data!W9)<=20 -> TRUE | AH9: =IFERROR(ISNUMBER(data!X9), FALSE) -> FALSE | AI9: =IF(ISERROR(MATCH(data!Y9, rule_mapping!$D$2:$D$252, 0))=FALSE,TRUE, FALSE) -> FALSE | AJ9: =IFERROR(ISNUMBER(data!Z9), FALSE) -> FALSE | AK9: =IFERROR(ISNUMBER(data!AA9), FALSE) -> FALSE | AL9: =LEN(data!AB9)<=90 -> TRUE | AM9: =LEN(data!AC9)>0 -> FALSE | AN9: =LEN(data!AC9)<=2000 -> TRUE | AO9: =IF(LEN(data!AD9)=0,TRUE,IF(LEN(data!AD9)=5,TRUE,FALSE)) -> TRUE | AP9: =LEN(data!AE9)>0 -> FALSE | AQ9: =LEN(data!AE9)=5 -> FALSE | AR9: =ISERROR(MATCH(data!AF9, rule_mapping!$B$2:$B$3, 0))=FALSE -> FALSE | AS9: =ISERROR(MATCH(data!AG9, rule_mapping!$A$2:$A$8, 0))=FALSE -> FALSE | AT9: =LEN(data!AH9)<=4 -> TRUE | AU9: =LEN(data!AI9)<=10 -> TRUE | AV9: =LEN(data!AJ9)<=35 -> TRUE | AW9: =LEN(data!AK9)<=20 -> TRUE | AX9: =CONCATENATE(IF(NOT(B9), B$1 & CHAR(10), ""), IF(NOT(C9), C$1 & CHAR(10), ""), IF(NOT(D9), D$1 & CHAR(10), ""), IF(NOT(E9), E$1 & CHAR(10), ""), IF(NOT(F9), F$1 & CHAR(10), ""), IF(NOT(G9), G$1 & CHAR(10), ""), IF(NOT(H9), H$1 & CHAR(10), ""), IF(NOT(I9), I$1 & CHAR(10), ""), IF(NOT(J9), J$1 & CHAR(10), ""), IF(NOT(K9), K$1 & CHAR(10), ""), IF(NOT(L9), L$1 & CHAR(10), ""), IF(NOT(M9), M$1 & CHAR(10), ""), IF(NOT(N9), N$1 & CHAR(10), ""), IF(NOT(O9), O$1 & CHAR(10), ""), IF(NOT(P9), P$1 & CHAR(10), ""), IF(NOT(Q9), Q$1 & CHAR(10), ""), IF(NOT(R9), R$1 & CHAR(10), ""), IF(NOT(S9), S$1 & CHAR(10), ""), IF(NOT(T9), T$1 & CHAR(10), ""), IF(NOT(U9), U$1 & CHAR(10), ""), IF(NOT(V9), V$1 & CHAR(10), ""), IF(NOT(W9), W$1 & CHAR(10), ""), IF(NOT(X9), X$1 & CHAR(10), ""), IF(NOT(Y9), Y$1 & CHAR(10), ""), IF(NOT(Z9), Z$1 & CHAR(10), ""), IF(NOT(AA9), AA$1 & CHAR(10), ""), IF(NOT(AB9), AB$1 & CHAR(10), ""), IF(NOT(AC9), AC$1 & CHAR(10), ""), IF(NOT(AD9), AD$1 & CHAR(10), ""), IF(NOT(AE9), AE$1 & CHAR(10), ""), IF(NOT(AF9), AF$1 & CHAR(10), ""), IF(NOT(AG9), AG$1 & CHAR(10), ""), IF(NOT(AH9), AH$1 & CHAR(10), ""), IF(NOT(AI9), AI$1 & CHAR(10), ""), IF(NOT(AJ9), AJ$1 & CHAR(10), ""), IF(NOT(AK9), AK$1 & CHAR(10), ""), IF(NOT(AL9), AL$1 & CHAR(10), ""), IF(NOT(AM9), AM$1 & CHAR(10), ""), IF(NOT(AN9), AN$1 & CHAR(10), ""), IF(NOT(AO9), AO$1 & CHAR(10), ""), IF(NOT(AP9), AP$1 & CHAR(10), ""), IF(NOT(AQ9), AQ$1 & CHAR(10), ""), IF(NOT(AR9), AR$1 & CHAR(10), ""), IF(NOT(AS9), AS$1 & CHAR(10), ""), IF(NOT(AT9), AT$1 & CHAR(10), ""), IF(NOT(AU9), AU$1 & CHAR(10), ""), IF(NOT(AV9), AV$1 & CHAR(10), ""), IF(NOT(AW9), AW$1 & CHAR(10), "")) -> 关单号 应以OOLU开头 缺少 发货人名称 缺少 发货人地址 缺少 发货人城市 发货人国家编码 应为2个字符 缺少 发货人联系电话 缺少 收货人名称 缺少 收货人地址 缺少 收货人城市 收货人国家编码 应为2个字符 缺少 收货人联系电话 缺少 通知人名称 缺少 通知人地址 缺少 通知人城市 通知人国家编码 应为2个字符 缺少 通知人联系电话 箱号 应为11个字符 尺寸箱型 错误 （请参照“箱型尺寸 ” 页） 缺少 铅封号 件数 应为数字 包装代码 错误（请参照“包装代码”页） 货物毛重(kg) 应为数字 体积 (m3) 应为数字 缺少 品名 缺少 目的港 目的港 应为5个字符 付费方式代码 错误 （请参照“付款方式代码”页） 运输条款代码 错误（请参照“运输条款”页）
A10: =OR(ISBLANK(data!B10), AND(B10:AW10)) -> TRUE | B10: =AND(LEFT(TRIM(data!B10), 4)="OOLU", ISNUMBER(RIGHT(TRIM(data!B10), LEN(TRIM(data!B10))-4)+0)) -> FALSE | C10: =LEN(data!C10)>0 -> FALSE | D10: =LEN(data!C10)<=70 -> TRUE | E10: =LEN(data!D10)>0 -> FALSE | F10: =LEN(data!D10)<=140 -> TRUE | G10: =LEN(data!E10)>0 -> FALSE | H10: =LEN(data!E10)<=35 -> TRUE | I10: =LEN(data!F10)=2 -> FALSE | J10: =LEN(data!G10)>0 -> FALSE | K10: =LEN(data!G10)<=60 -> TRUE | L10: =LEN(data!I10)>0 -> FALSE | M10: =LEN(data!I10)<=70 -> TRUE | N10: =LEN(data!J10)>0 -> FALSE | O10: =LEN(data!J10)<=140 -> TRUE | P10: =LEN(data!K10)>0 -> FALSE | Q10: =LEN(data!K10)<=35 -> TRUE | R10: =LEN(data!L10)=2 -> FALSE | S10: =LEN(data!M10)>0 -> FALSE | T10: =LEN(data!M10)<=60 -> TRUE | U10: =LEN(data!O10)>0 -> FALSE | V10: =LEN(data!O10)<=70 -> TRUE | W10: =LEN(data!P10)>0 -> FALSE | X10: =LEN(data!P10)<=140 -> TRUE | Y10: =LEN(data!Q10)>0 -> FALSE | Z10: =LEN(data!Q10)<=35 -> TRUE | AA10: =LEN(data!R10)=2 -> FALSE | AB10: =LEN(data!S10)>0 -> FALSE | AC10: =LEN(data!S10)<=120 -> TRUE | AD10: =LEN(data!U10)=11 -> FALSE | AE10: =AND(ISERROR(MATCH(data!V10, rule_mapping!$C$2:$C$325, 0))=FALSE, LEN(data!V10) <= 4) -> FALSE | AF10: =LEN(data!W10)>0 -> FALSE | AG10: =LEN(data!W10)<=20 -> TRUE | AH10: =IFERROR(ISNUMBER(data!X10), FALSE) -> FALSE | AI10: =IF(ISERROR(MATCH(data!Y10, rule_mapping!$D$2:$D$252, 0))=FALSE,TRUE, FALSE) -> FALSE | AJ10: =IFERROR(ISNUMBER(data!Z10), FALSE) -> FALSE | AK10: =IFERROR(ISNUMBER(data!AA10), FALSE) -> FALSE | AL10: =LEN(data!AB10)<=90 -> TRUE | AM10: =LEN(data!AC10)>0 -> FALSE | AN10: =LEN(data!AC10)<=2000 -> TRUE | AO10: =IF(LEN(data!AD10)=0,TRUE,IF(LEN(data!AD10)=5,TRUE,FALSE)) -> TRUE | AP10: =LEN(data!AE10)>0 -> FALSE | AQ10: =LEN(data!AE10)=5 -> FALSE | AR10: =ISERROR(MATCH(data!AF10, rule_mapping!$B$2:$B$3, 0))=FALSE -> FALSE | AS10: =ISERROR(MATCH(data!AG10, rule_mapping!$A$2:$A$8, 0))=FALSE -> FALSE | AT10: =LEN(data!AH10)<=4 -> TRUE | AU10: =LEN(data!AI10)<=10 -> TRUE | AV10: =LEN(data!AJ10)<=35 -> TRUE | AW10: =LEN(data!AK10)<=20 -> TRUE | AX10: =CONCATENATE(IF(NOT(B10), B$1 & CHAR(10), ""), IF(NOT(C10), C$1 & CHAR(10), ""), IF(NOT(D10), D$1 & CHAR(10), ""), IF(NOT(E10), E$1 & CHAR(10), ""), IF(NOT(F10), F$1 & CHAR(10), ""), IF(NOT(G10), G$1 & CHAR(10), ""), IF(NOT(H10), H$1 & CHAR(10), ""), IF(NOT(I10), I$1 & CHAR(10), ""), IF(NOT(J10), J$1 & CHAR(10), ""), IF(NOT(K10), K$1 & CHAR(10), ""), IF(NOT(L10), L$1 & CHAR(10), ""), IF(NOT(M10), M$1 & CHAR(10), ""), IF(NOT(N10), N$1 & CHAR(10), ""), IF(NOT(O10), O$1 & CHAR(10), ""), IF(NOT(P10), P$1 & CHAR(10), ""), IF(NOT(Q10), Q$1 & CHAR(10), ""), IF(NOT(R10), R$1 & CHAR(10), ""), IF(NOT(S10), S$1 & CHAR(10), ""), IF(NOT(T10), T$1 & CHAR(10), ""), IF(NOT(U10), U$1 & CHAR(10), ""), IF(NOT(V10), V$1 & CHAR(10), ""), IF(NOT(W10), W$1 & CHAR(10), ""), IF(NOT(X10), X$1 & CHAR(10), ""), IF(NOT(Y10), Y$1 & CHAR(10), ""), IF(NOT(Z10), Z$1 & CHAR(10), ""), IF(NOT(AA10), AA$1 & CHAR(10), ""), IF(NOT(AB10), AB$1 & CHAR(10), ""), IF(NOT(AC10), AC$1 & CHAR(10), ""), IF(NOT(AD10), AD$1 & CHAR(10), ""), IF(NOT(AE10), AE$1 & CHAR(10), ""), IF(NOT(AF10), AF$1 & CHAR(10), ""), IF(NOT(AG10), AG$1 & CHAR(10), ""), IF(NOT(AH10), AH$1 & CHAR(10), ""), IF(NOT(AI10), AI$1 & CHAR(10), ""), IF(NOT(AJ10), AJ$1 & CHAR(10), ""), IF(NOT(AK10), AK$1 & CHAR(10), ""), IF(NOT(AL10), AL$1 & CHAR(10), ""), IF(NOT(AM10), AM$1 & CHAR(10), ""), IF(NOT(AN10), AN$1 & CHAR(10), ""), IF(NOT(AO10), AO$1 & CHAR(10), ""), IF(NOT(AP10), AP$1 & CHAR(10), ""), IF(NOT(AQ10), AQ$1 & CHAR(10), ""), IF(NOT(AR10), AR$1 & CHAR(10), ""), IF(NOT(AS10), AS$1 & CHAR(10), ""), IF(NOT(AT10), AT$1 & CHAR(10), ""), IF(NOT(AU10), AU$1 & CHAR(10), ""), IF(NOT(AV10), AV$1 & CHAR(10), ""), IF(NOT(AW10), AW$1 & CHAR(10), "")) -> 关单号 应以OOLU开头 缺少 发货人名称 缺少 发货人地址 缺少 发货人城市 发货人国家编码 应为2个字符 缺少 发货人联系电话 缺少 收货人名称 缺少 收货人地址 缺少 收货人城市 收货人国家编码 应为2个字符 缺少 收货人联系电话 缺少 通知人名称 缺少 通知人地址 缺少 通知人城市 通知人国家编码 应为2个字符 缺少 通知人联系电话 箱号 应为11个字符 尺寸箱型 错误 （请参照“箱型尺寸 ” 页） 缺少 铅封号 件数 应为数字 包装代码 错误（请参照“包装代码”页） 货物毛重(kg) 应为数字 体积 (m3) 应为数字 缺少 品名 缺少 目的港 目的港 应为5个字符 付费方式代码 错误 （请参照“付款方式代码”页） 运输条款代码 错误（请参照“运输条款”页）
A11: =OR(ISBLANK(data!B11), AND(B11:AW11)) -> TRUE | B11: =AND(LEFT(TRIM(data!B11), 4)="OOLU", ISNUMBER(RIGHT(TRIM(data!B11), LEN(TRIM(data!B11))-4)+0)) -> FALSE | C11: =LEN(data!C11)>0 -> FALSE | D11: =LEN(data!C11)<=70 -> TRUE | E11: =LEN(data!D11)>0 -> FALSE | F11: =LEN(data!D11)<=140 -> TRUE | G11: =LEN(data!E11)>0 -> FALSE | H11: =LEN(data!E11)<=35 -> TRUE | I11: =LEN(data!F11)=2 -> FALSE | J11: =LEN(data!G11)>0 -> FALSE | K11: =LEN(data!G11)<=60 -> TRUE | L11: =LEN(data!I11)>0 -> FALSE | M11: =LEN(data!I11)<=70 -> TRUE | N11: =LEN(data!J11)>0 -> FALSE | O11: =LEN(data!J11)<=140 -> TRUE | P11: =LEN(data!K11)>0 -> FALSE | Q11: =LEN(data!K11)<=35 -> TRUE | R11: =LEN(data!L11)=2 -> FALSE | S11: =LEN(data!M11)>0 -> FALSE | T11: =LEN(data!M11)<=60 -> TRUE | U11: =LEN(data!O11)>0 -> FALSE | V11: =LEN(data!O11)<=70 -> TRUE | W11: =LEN(data!P11)>0 -> FALSE | X11: =LEN(data!P11)<=140 -> TRUE | Y11: =LEN(data!Q11)>0 -> FALSE | Z11: =LEN(data!Q11)<=35 -> TRUE | AA11: =LEN(data!R11)=2 -> FALSE | AB11: =LEN(data!S11)>0 -> FALSE | AC11: =LEN(data!S11)<=120 -> TRUE | AD11: =LEN(data!U11)=11 -> FALSE | AE11: =AND(ISERROR(MATCH(data!V11, rule_mapping!$C$2:$C$325, 0))=FALSE, LEN(data!V11) <= 4) -> FALSE | AF11: =LEN(data!W11)>0 -> FALSE | AG11: =LEN(data!W11)<=20 -> TRUE | AH11: =IFERROR(ISNUMBER(data!X11), FALSE) -> FALSE | AI11: =IF(ISERROR(MATCH(data!Y11, rule_mapping!$D$2:$D$252, 0))=FALSE,TRUE, FALSE) -> FALSE | AJ11: =IFERROR(ISNUMBER(data!Z11), FALSE) -> FALSE | AK11: =IFERROR(ISNUMBER(data!AA11), FALSE) -> FALSE | AL11: =LEN(data!AB11)<=90 -> TRUE | AM11: =LEN(data!AC11)>0 -> FALSE | AN11: =LEN(data!AC11)<=2000 -> TRUE | AO11: =IF(LEN(data!AD11)=0,TRUE,IF(LEN(data!AD11)=5,TRUE,FALSE)) -> TRUE | AP11: =LEN(data!AE11)>0 -> FALSE | AQ11: =LEN(data!AE11)=5 -> FALSE | AR11: =ISERROR(MATCH(data!AF11, rule_mapping!$B$2:$B$3, 0))=FALSE -> FALSE | AS11: =ISERROR(MATCH(data!AG11, rule_mapping!$A$2:$A$8, 0))=FALSE -> FALSE | AT11: =LEN(data!AH11)<=4 -> TRUE | AU11: =LEN(data!AI11)<=10 -> TRUE | AV11: =LEN(data!AJ11)<=35 -> TRUE | AW11: =LEN(data!AK11)<=20 -> TRUE | AX11: =CONCATENATE(IF(NOT(B11), B$1 & CHAR(10), ""), IF(NOT(C11), C$1 & CHAR(10), ""), IF(NOT(D11), D$1 & CHAR(10), ""), IF(NOT(E11), E$1 & CHAR(10), ""), IF(NOT(F11), F$1 & CHAR(10), ""), IF(NOT(G11), G$1 & CHAR(10), ""), IF(NOT(H11), H$1 & CHAR(10), ""), IF(NOT(I11), I$1 & CHAR(10), ""), IF(NOT(J11), J$1 & CHAR(10), ""), IF(NOT(K11), K$1 & CHAR(10), ""), IF(NOT(L11), L$1 & CHAR(10), ""), IF(NOT(M11), M$1 & CHAR(10), ""), IF(NOT(N11), N$1 & CHAR(10), ""), IF(NOT(O11), O$1 & CHAR(10), ""), IF(NOT(P11), P$1 & CHAR(10), ""), IF(NOT(Q11), Q$1 & CHAR(10), ""), IF(NOT(R11), R$1 & CHAR(10), ""), IF(NOT(S11), S$1 & CHAR(10), ""), IF(NOT(T11), T$1 & CHAR(10), ""), IF(NOT(U11), U$1 & CHAR(10), ""), IF(NOT(V11), V$1 & CHAR(10), ""), IF(NOT(W11), W$1 & CHAR(10), ""), IF(NOT(X11), X$1 & CHAR(10), ""), IF(NOT(Y11), Y$1 & CHAR(10), ""), IF(NOT(Z11), Z$1 & CHAR(10), ""), IF(NOT(AA11), AA$1 & CHAR(10), ""), IF(NOT(AB11), AB$1 & CHAR(10), ""), IF(NOT(AC11), AC$1 & CHAR(10), ""), IF(NOT(AD11), AD$1 & CHAR(10), ""), IF(NOT(AE11), AE$1 & CHAR(10), ""), IF(NOT(AF11), AF$1 & CHAR(10), ""), IF(NOT(AG11), AG$1 & CHAR(10), ""), IF(NOT(AH11), AH$1 & CHAR(10), ""), IF(NOT(AI11), AI$1 & CHAR(10), ""), IF(NOT(AJ11), AJ$1 & CHAR(10), ""), IF(NOT(AK11), AK$1 & CHAR(10), ""), IF(NOT(AL11), AL$1 & CHAR(10), ""), IF(NOT(AM11), AM$1 & CHAR(10), ""), IF(NOT(AN11), AN$1 & CHAR(10), ""), IF(NOT(AO11), AO$1 & CHAR(10), ""), IF(NOT(AP11), AP$1 & CHAR(10), ""), IF(NOT(AQ11), AQ$1 & CHAR(10), ""), IF(NOT(AR11), AR$1 & CHAR(10), ""), IF(NOT(AS11), AS$1 & CHAR(10), ""), IF(NOT(AT11), AT$1 & CHAR(10), ""), IF(NOT(AU11), AU$1 & CHAR(10), ""), IF(NOT(AV11), AV$1 & CHAR(10), ""), IF(NOT(AW11), AW$1 & CHAR(10), "")) -> 关单号 应以OOLU开头 缺少 发货人名称 缺少 发货人地址 缺少 发货人城市 发货人国家编码 应为2个字符 缺少 发货人联系电话 缺少 收货人名称 缺少 收货人地址 缺少 收货人城市 收货人国家编码 应为2个字符 缺少 收货人联系电话 缺少 通知人名称 缺少 通知人地址 缺少 通知人城市 通知人国家编码 应为2个字符 缺少 通知人联系电话 箱号 应为11个字符 尺寸箱型 错误 （请参照“箱型尺寸 ” 页） 缺少 铅封号 件数 应为数字 包装代码 错误（请参照“包装代码”页） 货物毛重(kg) 应为数字 体积 (m3) 应为数字 缺少 品名 缺少 目的港 目的港 应为5个字符 付费方式代码 错误 （请参照“付款方式代码”页） 运输条款代码 错误（请参照“运输条款”页）
A12: =OR(ISBLANK(data!B12), AND(B12:AW12)) -> TRUE | B12: =AND(LEFT(TRIM(data!B12), 4)="OOLU", ISNUMBER(RIGHT(TRIM(data!B12), LEN(TRIM(data!B12))-4)+0)) -> FALSE | C12: =LEN(data!C12)>0 -> FALSE | D12: =LEN(data!C12)<=70 -> TRUE | E12: =LEN(data!D12)>0 -> FALSE | F12: =LEN(data!D12)<=140 -> TRUE | G12: =LEN(data!E12)>0 -> FALSE | H12: =LEN(data!E12)<=35 -> TRUE | I12: =LEN(data!F12)=2 -> FALSE | J12: =LEN(data!G12)>0 -> FALSE | K12: =LEN(data!G12)<=60 -> TRUE | L12: =LEN(data!I12)>0 -> FALSE | M12: =LEN(data!I12)<=70 -> TRUE | N12: =LEN(data!J12)>0 -> FALSE | O12: =LEN(data!J12)<=140 -> TRUE | P12: =LEN(data!K12)>0 -> FALSE | Q12: =LEN(data!K12)<=35 -> TRUE | R12: =LEN(data!L12)=2 -> FALSE | S12: =LEN(data!M12)>0 -> FALSE | T12: =LEN(data!M12)<=60 -> TRUE | U12: =LEN(data!O12)>0 -> FALSE | V12: =LEN(data!O12)<=70 -> TRUE | W12: =LEN(data!P12)>0 -> FALSE | X12: =LEN(data!P12)<=140 -> TRUE | Y12: =LEN(data!Q12)>0 -> FALSE | Z12: =LEN(data!Q12)<=35 -> TRUE | AA12: =LEN(data!R12)=2 -> FALSE | AB12: =LEN(data!S12)>0 -> FALSE | AC12: =LEN(data!S12)<=120 -> TRUE | AD12: =LEN(data!U12)=11 -> FALSE | AE12: =AND(ISERROR(MATCH(data!V12, rule_mapping!$C$2:$C$325, 0))=FALSE, LEN(data!V12) <= 4) -> FALSE | AF12: =LEN(data!W12)>0 -> FALSE | AG12: =LEN(data!W12)<=20 -> TRUE | AH12: =IFERROR(ISNUMBER(data!X12), FALSE) -> FALSE | AI12: =IF(ISERROR(MATCH(data!Y12, rule_mapping!$D$2:$D$252, 0))=FALSE,TRUE, FALSE) -> FALSE | AJ12: =IFERROR(ISNUMBER(data!Z12), FALSE) -> FALSE | AK12: =IFERROR(ISNUMBER(data!AA12), FALSE) -> FALSE | AL12: =LEN(data!AB12)<=90 -> TRUE | AM12: =LEN(data!AC12)>0 -> FALSE | AN12: =LEN(data!AC12)<=2000 -> TRUE | AO12: =IF(LEN(data!AD12)=0,TRUE,IF(LEN(data!AD12)=5,TRUE,FALSE)) -> TRUE | AP12: =LEN(data!AE12)>0 -> FALSE | AQ12: =LEN(data!AE12)=5 -> FALSE | AR12: =ISERROR(MATCH(data!AF12, rule_mapping!$B$2:$B$3, 0))=FALSE -> FALSE | AS12: =ISERROR(MATCH(data!AG12, rule_mapping!$A$2:$A$8, 0))=FALSE -> FALSE | AT12: =LEN(data!AH12)<=4 -> TRUE | AU12: =LEN(data!AI12)<=10 -> TRUE | AV12: =LEN(data!AJ12)<=35 -> TRUE | AW12: =LEN(data!AK12)<=20 -> TRUE | AX12: =CONCATENATE(IF(NOT(B12), B$1 & CHAR(10), ""), IF(NOT(C12), C$1 & CHAR(10), ""), IF(NOT(D12), D$1 & CHAR(10), ""), IF(NOT(E12), E$1 & CHAR(10), ""), IF(NOT(F12), F$1 & CHAR(10), ""), IF(NOT(G12), G$1 & CHAR(10), ""), IF(NOT(H12), H$1 & CHAR(10), ""), IF(NOT(I12), I$1 & CHAR(10), ""), IF(NOT(J12), J$1 & CHAR(10), ""), IF(NOT(K12), K$1 & CHAR(10), ""), IF(NOT(L12), L$1 & CHAR(10), ""), IF(NOT(M12), M$1 & CHAR(10), ""), IF(NOT(N12), N$1 & CHAR(10), ""), IF(NOT(O12), O$1 & CHAR(10), ""), IF(NOT(P12), P$1 & CHAR(10), ""), IF(NOT(Q12), Q$1 & CHAR(10), ""), IF(NOT(R12), R$1 & CHAR(10), ""), IF(NOT(S12), S$1 & CHAR(10), ""), IF(NOT(T12), T$1 & CHAR(10), ""), IF(NOT(U12), U$1 & CHAR(10), ""), IF(NOT(V12), V$1 & CHAR(10), ""), IF(NOT(W12), W$1 & CHAR(10), ""), IF(NOT(X12), X$1 & CHAR(10), ""), IF(NOT(Y12), Y$1 & CHAR(10), ""), IF(NOT(Z12), Z$1 & CHAR(10), ""), IF(NOT(AA12), AA$1 & CHAR(10), ""), IF(NOT(AB12), AB$1 & CHAR(10), ""), IF(NOT(AC12), AC$1 & CHAR(10), ""), IF(NOT(AD12), AD$1 & CHAR(10), ""), IF(NOT(AE12), AE$1 & CHAR(10), ""), IF(NOT(AF12), AF$1 & CHAR(10), ""), IF(NOT(AG12), AG$1 & CHAR(10), ""), IF(NOT(AH12), AH$1 & CHAR(10), ""), IF(NOT(AI12), AI$1 & CHAR(10), ""), IF(NOT(AJ12), AJ$1 & CHAR(10), ""), IF(NOT(AK12), AK$1 & CHAR(10), ""), IF(NOT(AL12), AL$1 & CHAR(10), ""), IF(NOT(AM12), AM$1 & CHAR(10), ""), IF(NOT(AN12), AN$1 & CHAR(10), ""), IF(NOT(AO12), AO$1 & CHAR(10), ""), IF(NOT(AP12), AP$1 & CHAR(10), ""), IF(NOT(AQ12), AQ$1 & CHAR(10), ""), IF(NOT(AR12), AR$1 & CHAR(10), ""), IF(NOT(AS12), AS$1 & CHAR(10), ""), IF(NOT(AT12), AT$1 & CHAR(10), ""), IF(NOT(AU12), AU$1 & CHAR(10), ""), IF(NOT(AV12), AV$1 & CHAR(10), ""), IF(NOT(AW12), AW$1 & CHAR(10), "")) -> 关单号 应以OOLU开头 缺少 发货人名称 缺少 发货人地址 缺少 发货人城市 发货人国家编码 应为2个字符 缺少 发货人联系电话 缺少 收货人名称 缺少 收货人地址 缺少 收货人城市 收货人国家编码 应为2个字符 缺少 收货人联系电话 缺少 通知人名称 缺少 通知人地址 缺少 通知人城市 通知人国家编码 应为2个字符 缺少 通知人联系电话 箱号 应为11个字符 尺寸箱型 错误 （请参照“箱型尺寸 ” 页） 缺少 铅封号 件数 应为数字 包装代码 错误（请参照“包装代码”页） 货物毛重(kg) 应为数字 体积 (m3) 应为数字 缺少 品名 缺少 目的港 目的港 应为5个字符 付费方式代码 错误 （请参照“付款方式代码”页） 运输条款代码 错误（请参照“运输条款”页）
A13: =OR(ISBLANK(data!B13), AND(B13:AW13)) -> TRUE | B13: =AND(LEFT(TRIM(data!B13), 4)="OOLU", ISNUMBER(RIGHT(TRIM(data!B13), LEN(TRIM(data!B13))-4)+0)) -> FALSE | C13: =LEN(data!C13)>0 -> FALSE | D13: =LEN(data!C13)<=70 -> TRUE | E13: =LEN(data!D13)>0 -> FALSE | F13: =LEN(data!D13)<=140 -> TRUE | G13: =LEN(data!E13)>0 -> FALSE | H13: =LEN(data!E13)<=35 -> TRUE | I13: =LEN(data!F13)=2 -> FALSE | J13: =LEN(data!G13)>0 -> FALSE | K13: =LEN(data!G13)<=60 -> TRUE | L13: =LEN(data!I13)>0 -> FALSE | M13: =LEN(data!I13)<=70 -> TRUE | N13: =LEN(data!J13)>0 -> FALSE | O13: =LEN(data!J13)<=140 -> TRUE | P13: =LEN(data!K13)>0 -> FALSE | Q13: =LEN(data!K13)<=35 -> TRUE | R13: =LEN(data!L13)=2 -> FALSE | S13: =LEN(data!M13)>0 -> FALSE | T13: =LEN(data!M13)<=60 -> TRUE | U13: =LEN(data!O13)>0 -> FALSE | V13: =LEN(data!O13)<=70 -> TRUE | W13: =LEN(data!P13)>0 -> FALSE | X13: =LEN(data!P13)<=140 -> TRUE | Y13: =LEN(data!Q13)>0 -> FALSE | Z13: =LEN(data!Q13)<=35 -> TRUE | AA13: =LEN(data!R13)=2 -> FALSE | AB13: =LEN(data!S13)>0 -> FALSE | AC13: =LEN(data!S13)<=120 -> TRUE | AD13: =LEN(data!U13)=11 -> FALSE | AE13: =AND(ISERROR(MATCH(data!V13, rule_mapping!$C$2:$C$325, 0))=FALSE, LEN(data!V13) <= 4) -> FALSE | AF13: =LEN(data!W13)>0 -> FALSE | AG13: =LEN(data!W13)<=20 -> TRUE | AH13: =IFERROR(ISNUMBER(data!X13), FALSE) -> FALSE | AI13: =IF(ISERROR(MATCH(data!Y13, rule_mapping!$D$2:$D$252, 0))=FALSE,TRUE, FALSE) -> FALSE | AJ13: =IFERROR(ISNUMBER(data!Z13), FALSE) -> FALSE | AK13: =IFERROR(ISNUMBER(data!AA13), FALSE) -> FALSE | AL13: =LEN(data!AB13)<=90 -> TRUE | AM13: =LEN(data!AC13)>0 -> FALSE | AN13: =LEN(data!AC13)<=2000 -> TRUE | AO13: =IF(LEN(data!AD13)=0,TRUE,IF(LEN(data!AD13)=5,TRUE,FALSE)) -> TRUE | AP13: =LEN(data!AE13)>0 -> FALSE | AQ13: =LEN(data!AE13)=5 -> FALSE | AR13: =ISERROR(MATCH(data!AF13, rule_mapping!$B$2:$B$3, 0))=FALSE -> FALSE | AS13: =ISERROR(MATCH(data!AG13, rule_mapping!$A$2:$A$8, 0))=FALSE -> FALSE | AT13: =LEN(data!AH13)<=4 -> TRUE | AU13: =LEN(data!AI13)<=10 -> TRUE | AV13: =LEN(data!AJ13)<=35 -> TRUE | AW13: =LEN(data!AK13)<=20 -> TRUE | AX13: =CONCATENATE(IF(NOT(B13), B$1 & CHAR(10), ""), IF(NOT(C13), C$1 & CHAR(10), ""), IF(NOT(D13), D$1 & CHAR(10), ""), IF(NOT(E13), E$1 & CHAR(10), ""), IF(NOT(F13), F$1 & CHAR(10), ""), IF(NOT(G13), G$1 & CHAR(10), ""), IF(NOT(H13), H$1 & CHAR(10), ""), IF(NOT(I13), I$1 & CHAR(10), ""), IF(NOT(J13), J$1 & CHAR(10), ""), IF(NOT(K13), K$1 & CHAR(10), ""), IF(NOT(L13), L$1 & CHAR(10), ""), IF(NOT(M13), M$1 & CHAR(10), ""), IF(NOT(N13), N$1 & CHAR(10), ""), IF(NOT(O13), O$1 & CHAR(10), ""), IF(NOT(P13), P$1 & CHAR(10), ""), IF(NOT(Q13), Q$1 & CHAR(10), ""), IF(NOT(R13), R$1 & CHAR(10), ""), IF(NOT(S13), S$1 & CHAR(10), ""), IF(NOT(T13), T$1 & CHAR(10), ""), IF(NOT(U13), U$1 & CHAR(10), ""), IF(NOT(V13), V$1 & CHAR(10), ""), IF(NOT(W13), W$1 & CHAR(10), ""), IF(NOT(X13), X$1 & CHAR(10), ""), IF(NOT(Y13), Y$1 & CHAR(10), ""), IF(NOT(Z13), Z$1 & CHAR(10), ""), IF(NOT(AA13), AA$1 & CHAR(10), ""), IF(NOT(AB13), AB$1 & CHAR(10), ""), IF(NOT(AC13), AC$1 & CHAR(10), ""), IF(NOT(AD13), AD$1 & CHAR(10), ""), IF(NOT(AE13), AE$1 & CHAR(10), ""), IF(NOT(AF13), AF$1 & CHAR(10), ""), IF(NOT(AG13), AG$1 & CHAR(10), ""), IF(NOT(AH13), AH$1 & CHAR(10), ""), IF(NOT(AI13), AI$1 & CHAR(10), ""), IF(NOT(AJ13), AJ$1 & CHAR(10), ""), IF(NOT(AK13), AK$1 & CHAR(10), ""), IF(NOT(AL13), AL$1 & CHAR(10), ""), IF(NOT(AM13), AM$1 & CHAR(10), ""), IF(NOT(AN13), AN$1 & CHAR(10), ""), IF(NOT(AO13), AO$1 & CHAR(10), ""), IF(NOT(AP13), AP$1 & CHAR(10), ""), IF(NOT(AQ13), AQ$1 & CHAR(10), ""), IF(NOT(AR13), AR$1 & CHAR(10), ""), IF(NOT(AS13), AS$1 & CHAR(10), ""), IF(NOT(AT13), AT$1 & CHAR(10), ""), IF(NOT(AU13), AU$1 & CHAR(10), ""), IF(NOT(AV13), AV$1 & CHAR(10), ""), IF(NOT(AW13), AW$1 & CHAR(10), "")) -> 关单号 应以OOLU开头 缺少 发货人名称 缺少 发货人地址 缺少 发货人城市 发货人国家编码 应为2个字符 缺少 发货人联系电话 缺少 收货人名称 缺少 收货人地址 缺少 收货人城市 收货人国家编码 应为2个字符 缺少 收货人联系电话 缺少 通知人名称 缺少 通知人地址 缺少 通知人城市 通知人国家编码 应为2个字符 缺少 通知人联系电话 箱号 应为11个字符 尺寸箱型 错误 （请参照“箱型尺寸 ” 页） 缺少 铅封号 件数 应为数字 包装代码 错误（请参照“包装代码”页） 货物毛重(kg) 应为数字 体积 (m3) 应为数字 缺少 品名 缺少 目的港 目的港 应为5个字符 付费方式代码 错误 （请参照“付款方式代码”页） 运输条款代码 错误（请参照“运输条款”页）
A14: =OR(ISBLANK(data!B14), AND(B14:AW14)) -> TRUE | B14: =AND(LEFT(TRIM(data!B14), 4)="OOLU", ISNUMBER(RIGHT(TRIM(data!B14), LEN(TRIM(data!B14))-4)+0)) -> FALSE | C14: =LEN(data!C14)>0 -> FALSE | D14: =LEN(data!C14)<=70 -> TRUE | E14: =LEN(data!D14)>0 -> FALSE | F14: =LEN(data!D14)<=140 -> TRUE | G14: =LEN(data!E14)>0 -> FALSE | H14: =LEN(data!E14)<=35 -> TRUE | I14: =LEN(data!F14)=2 -> FALSE | J14: =LEN(data!G14)>0 -> FALSE | K14: =LEN(data!G14)<=60 -> TRUE | L14: =LEN(data!I14)>0 -> FALSE | M14: =LEN(data!I14)<=70 -> TRUE | N14: =LEN(data!J14)>0 -> FALSE | O14: =LEN(data!J14)<=140 -> TRUE | P14: =LEN(data!K14)>0 -> FALSE | Q14: =LEN(data!K14)<=35 -> TRUE | R14: =LEN(data!L14)=2 -> FALSE | S14: =LEN(data!M14)>0 -> FALSE | T14: =LEN(data!M14)<=60 -> TRUE | U14: =LEN(data!O14)>0 -> FALSE | V14: =LEN(data!O14)<=70 -> TRUE | W14: =LEN(data!P14)>0 -> FALSE | X14: =LEN(data!P14)<=140 -> TRUE | Y14: =LEN(data!Q14)>0 -> FALSE | Z14: =LEN(data!Q14)<=35 -> TRUE | AA14: =LEN(data!R14)=2 -> FALSE | AB14: =LEN(data!S14)>0 -> FALSE | AC14: =LEN(data!S14)<=120 -> TRUE | AD14: =LEN(data!U14)=11 -> FALSE | AE14: =AND(ISERROR(MATCH(data!V14, rule_mapping!$C$2:$C$325, 0))=FALSE, LEN(data!V14) <= 4) -> FALSE | AF14: =LEN(data!W14)>0 -> FALSE | AG14: =LEN(data!W14)<=20 -> TRUE | AH14: =IFERROR(ISNUMBER(data!X14), FALSE) -> FALSE | AI14: =IF(ISERROR(MATCH(data!Y14, rule_mapping!$D$2:$D$252, 0))=FALSE,TRUE, FALSE) -> FALSE | AJ14: =IFERROR(ISNUMBER(data!Z14), FALSE) -> FALSE | AK14: =IFERROR(ISNUMBER(data!AA14), FALSE) -> FALSE | AL14: =LEN(data!AB14)<=90 -> TRUE | AM14: =LEN(data!AC14)>0 -> FALSE | AN14: =LEN(data!AC14)<=2000 -> TRUE | AO14: =IF(LEN(data!AD14)=0,TRUE,IF(LEN(data!AD14)=5,TRUE,FALSE)) -> TRUE | AP14: =LEN(data!AE14)>0 -> FALSE | AQ14: =LEN(data!AE14)=5 -> FALSE | AR14: =ISERROR(MATCH(data!AF14, rule_mapping!$B$2:$B$3, 0))=FALSE -> FALSE | AS14: =ISERROR(MATCH(data!AG14, rule_mapping!$A$2:$A$8, 0))=FALSE -> FALSE | AT14: =LEN(data!AH14)<=4 -> TRUE | AU14: =LEN(data!AI14)<=10 -> TRUE | AV14: =LEN(data!AJ14)<=35 -> TRUE | AW14: =LEN(data!AK14)<=20 -> TRUE | AX14: =CONCATENATE(IF(NOT(B14), B$1 & CHAR(10), ""), IF(NOT(C14), C$1 & CHAR(10), ""), IF(NOT(D14), D$1 & CHAR(10), ""), IF(NOT(E14), E$1 & CHAR(10), ""), IF(NOT(F14), F$1 & CHAR(10), ""), IF(NOT(G14), G$1 & CHAR(10), ""), IF(NOT(H14), H$1 & CHAR(10), ""), IF(NOT(I14), I$1 & CHAR(10), ""), IF(NOT(J14), J$1 & CHAR(10), ""), IF(NOT(K14), K$1 & CHAR(10), ""), IF(NOT(L14), L$1 & CHAR(10), ""), IF(NOT(M14), M$1 & CHAR(10), ""), IF(NOT(N14), N$1 & CHAR(10), ""), IF(NOT(O14), O$1 & CHAR(10), ""), IF(NOT(P14), P$1 & CHAR(10), ""), IF(NOT(Q14), Q$1 & CHAR(10), ""), IF(NOT(R14), R$1 & CHAR(10), ""), IF(NOT(S14), S$1 & CHAR(10), ""), IF(NOT(T14), T$1 & CHAR(10), ""), IF(NOT(U14), U$1 & CHAR(10), ""), IF(NOT(V14), V$1 & CHAR(10), ""), IF(NOT(W14), W$1 & CHAR(10), ""), IF(NOT(X14), X$1 & CHAR(10), ""), IF(NOT(Y14), Y$1 & CHAR(10), ""), IF(NOT(Z14), Z$1 & CHAR(10), ""), IF(NOT(AA14), AA$1 & CHAR(10), ""), IF(NOT(AB14), AB$1 & CHAR(10), ""), IF(NOT(AC14), AC$1 & CHAR(10), ""), IF(NOT(AD14), AD$1 & CHAR(10), ""), IF(NOT(AE14), AE$1 & CHAR(10), ""), IF(NOT(AF14), AF$1 & CHAR(10), ""), IF(NOT(AG14), AG$1 & CHAR(10), ""), IF(NOT(AH14), AH$1 & CHAR(10), ""), IF(NOT(AI14), AI$1 & CHAR(10), ""), IF(NOT(AJ14), AJ$1 & CHAR(10), ""), IF(NOT(AK14), AK$1 & CHAR(10), ""), IF(NOT(AL14), AL$1 & CHAR(10), ""), IF(NOT(AM14), AM$1 & CHAR(10), ""), IF(NOT(AN14), AN$1 & CHAR(10), ""), IF(NOT(AO14), AO$1 & CHAR(10), ""), IF(NOT(AP14), AP$1 & CHAR(10), ""), IF(NOT(AQ14), AQ$1 & CHAR(10), ""), IF(NOT(AR14), AR$1 & CHAR(10), ""), IF(NOT(AS14), AS$1 & CHAR(10), ""), IF(NOT(AT14), AT$1 & CHAR(10), ""), IF(NOT(AU14), AU$1 & CHAR(10), ""), IF(NOT(AV14), AV$1 & CHAR(10), ""), IF(NOT(AW14), AW$1 & CHAR(10), "")) -> 关单号 应以OOLU开头 缺少 发货人名称 缺少 发货人地址 缺少 发货人城市 发货人国家编码 应为2个字符 缺少 发货人联系电话 缺少 收货人名称 缺少 收货人地址 缺少 收货人城市 收货人国家编码 应为2个字符 缺少 收货人联系电话 缺少 通知人名称 缺少 通知人地址 缺少 通知人城市 通知人国家编码 应为2个字符 缺少 通知人联系电话 箱号 应为11个字符 尺寸箱型 错误 （请参照“箱型尺寸 ” 页） 缺少 铅封号 件数 应为数字 包装代码 错误（请参照“包装代码”页） 货物毛重(kg) 应为数字 体积 (m3) 应为数字 缺少 品名 缺少 目的港 目的港 应为5个字符 付费方式代码 错误 （请参照“付款方式代码”页） 运输条款代码 错误（请参照“运输条款”页）
